Workbook
Name _app1: IF(ISBLANK('Cover Sheet'!$I$67),"",'Cover Sheet'!$I$67)
Name _app2: IF(ISBLANK('Cover Sheet'!$I$66),"",'Cover Sheet'!$I$66)
Name _app3: IF(ISBLANK('Cover Sheet'!$I$65),"",'Cover Sheet'!$I$65)
Name _chk1: IF(ISBLANK('Cover Sheet'!$G$67),"",'Cover Sheet'!$G$67)
Name _chk2: IF(ISBLANK('Cover Sheet'!$G$66),"",'Cover Sheet'!$G$66)
Name _chk3: IF(ISBLANK('Cover Sheet'!$G$65),"",'Cover Sheet'!$G$65)
Name _rev1: IF(ISBLANK('Cover Sheet'!$A$67),"",'Cover Sheet'!$A$67)
Name _rev2: IF(ISBLANK('Cover Sheet'!$A$66),"",'Cover Sheet'!$A$66)
Name _rev3: IF(ISBLANK('Cover Sheet'!$A$65),"",'Cover Sheet'!$A$65)
Name a: '[1]High Frequency Acoustic Excit.'!#REF!
Name a: '[1]High Frequency Acoustic Excit.'!#REF!
Name a: '[1]High Frequency Acoustic Excit.'!#REF!
Name a: '[1]High Frequency Acoustic Excit.'!#REF!
Name a: '[1]High Frequency Acoustic Excit.'!#REF!
Name a: '[1]High Frequency Acoustic Excit.'!#REF!
Name a: '[1]High Frequency Acoustic Excit.'!#REF!
Name a: '[1]High Frequency Acoustic Excit.'!#REF!
Name a: '[1]High Frequency Acoustic Excit.'!#REF!
Name a: '[1]High Frequency Acoustic Excit.'!#REF!
Name a: '[1]High Frequency Acoustic Excit.'!#REF!
Name a: '[1]High Frequency Acoustic Excit.'!#REF!
Name B: '[1]High Frequency Acoustic Excit.'!#REF!
Name B: '[1]High Frequency Acoustic Excit.'!#REF!
Name B: '[1]High Frequency Acoustic Excit.'!#REF!
Name B: '[1]High Frequency Acoustic Excit.'!#REF!
Name B: '[1]High Frequency Acoustic Excit.'!#REF!
Name B: '[1]High Frequency Acoustic Excit.'!#REF!
Name B: '[1]High Frequency Acoustic Excit.'!#REF!
Name B: '[1]High Frequency Acoustic Excit.'!#REF!
Name B: '[1]High Frequency Acoustic Excit.'!#REF!
Name B: '[1]High Frequency Acoustic Excit.'!#REF!
Name B: '[1]High Frequency Acoustic Excit.'!#REF!
Name B: '[1]High Frequency Acoustic Excit.'!#REF!
Name Calc_No: IF(ISBLANK('Cover Sheet'!$H$3),"",'Cover Sheet'!$H$3)
Name calc_title: IF(ISBLANK('Cover Sheet'!$D$4),"",'Cover Sheet'!$D$4)
Name customer: IF(ISBLANK('Cover Sheet'!$D$2),"",'Cover Sheet'!$D$2)
Name date1: IF(ISBLANK('Cover Sheet'!$B$67),"",'Cover Sheet'!$B$67)
Name date2: IF(ISBLANK('Cover Sheet'!$B$66),"",'Cover Sheet'!$B$66)
Name date3: IF(ISBLANK('Cover Sheet'!$B$65),"",'Cover Sheet'!$B$65)
Name desc1: IF(ISBLANK('Cover Sheet'!$D$67),"",'Cover Sheet'!$D$67)
Name desc2: IF(ISBLANK('Cover Sheet'!$D$66),"",'Cover Sheet'!$D$66)
Name desc3: IF(ISBLANK('Cover Sheet'!$D$65),"",'Cover Sheet'!$D$65)
Name Dext: '[1]High Frequency Acoustic Excit.'!$D$15
Name disclaimer: 'Cover Sheet'!$A$69
Name elec_file: IF(ISBLANK('Cover Sheet'!$D$5),"",'Cover Sheet'!$D$5)
Name num_pages: IF(ISBLANK('Cover Sheet'!$J$6),"",'Cover Sheet'!$J$6)
Name orig1: IF(ISBLANK('Cover Sheet'!$F$67),"",'Cover Sheet'!$F$67)
Name orig2: IF(ISBLANK('Cover Sheet'!$F$66),"",'Cover Sheet'!$F$66)
Name orig3: IF(ISBLANK('Cover Sheet'!$F$65),"",'Cover Sheet'!$F$65)
Name Phase_CTR: IF(ISBLANK('Cover Sheet'!$H$4),"",'Cover Sheet'!$H$4)
Name proj_file: IF(ISBLANK('Cover Sheet'!$D$6),"",'Cover Sheet'!$D$6)
Name Proj_No: IF(ISBLANK('Cover Sheet'!$H$2),"",'Cover Sheet'!$H$2)
Name proj_title: IF(ISBLANK('Cover Sheet'!$D$3),"",'Cover Sheet'!$D$3)
Name s: '[1]High Frequency Acoustic Excit.'!#REF!
Name s: '[1]High Frequency Acoustic Excit.'!#REF!
Name s: '[1]High Frequency Acoustic Excit.'!#REF!
Name s: '[1]High Frequency Acoustic Excit.'!#REF!
Name s: '[1]High Frequency Acoustic Excit.'!#REF!
Name s: '[1]High Frequency Acoustic Excit.'!#REF!
Name s: '[1]High Frequency Acoustic Excit.'!#REF!

Sheet Cover Sheet
A1: Calculation Cover Sheet
A2: Customer | D2: customer name | G2: Proj No | H2: proj no
A3: Project Title | D3: proj title | G3: Calc No | H3: KS-PR-CAL-0090
A4: Calculation Title | D4: Vibration Assessment - Surge and Momentum Changes Template | G4: Phase/CTR | H4: phase
A5: Elec File Location | D5: =SUBSTITUTE(LEFT(CELL("filename"),FIND("]",CELL("filename"))-1),"[","") -> https://worleyparsons-my.sharepoint.com/personal/priyanka_verma_worley_com/Documents/Phase 2 QC2 Document Folder/KS/Calculations KS/Compare/KS-PR-CAL-0090 Vibration Assessment - Surge and Momentum Changes Template.xlsx
G6: Page | H6: 1 | I6: of | J6: 13
A7: Calculation Objective
A8: The objective of this calculation is to determine the main line likelihood of failure (LOF) for vibration induced fatigue due to surge/momentum changes due to valve operation for….
A13: Calculation Method
A14: The LOF calculation methodology is based on Energy Institute guidelines for the avoidance of vibration induced fatigue in process pipework (Ref. 1, Technical Module T2.9) and is summarized below: 1) Preliminary screening - Identify all the significant valves on a particular line. 2) Categorisation and LOF assignment The assesment is split into three potential operating cases: - Dry Gas Rapid Valve Opening. - Liquid Multiphase Valve Closure. - Liquid Multiphase Valve Opening. Each case is described in more detail in section 4. Additional guidance is provided in Worley Design Guide: "Avoidance of Vibration Induced Fatigue Failure in Process Pipework" (Ref. 2)
A25: Assumptions
A26: 1. System under consideration is a new design, part of an existing plant or change to existing plant that may exhibit or result in surge/momentum changes Due to valve operation (Ref. 1, Tables T2-6 and T2-7 and T2-8). 2. Excitation due to surge and momentum changes is only considered for fast acting valves, which excludes all manually operated valves (Ref. 1 Sec T2.8.1). 3. For a dry gas any potential surge pressure due to a rapid valve closure is taken up via compression of the gas, hence likelihood of failure due to a gas valve closing is considered negligible (Ref. 1 Sec T2.8.1). 4. The assumption is made that the line is adequately supported for any reaction loads and that any anchors have significant strength.
A41: Software Used
A42: Title | G42: Version | H42: Validation (Y / N / N/A)
A45: References
A46: 1. "Guidelines for the Avoidance of Vibration Induced Fatigue in Process Pipework" Energy Institute, 2nd Edition,January 2008 2. "Avoidance of Vibration Induced Fatigue Failure in Process Pipework", KS-PR-DEG-0166, Worley Design Guide, Rev 0, November 2016
A52: Conclusions
A60: Related to a Safety Critical System? | E60: No | F60: Status of Supplier Data used | H60: N/A
A61: HOLDS
A65: rev 3 | B65: date 3 | D65: desc 3 | F65: by 3 | G65: chkd 3 | I65: app 3
A66: rev 2 | B66: date 2 | D66: desc 2 | F66: by 2 | G66: chkd 2 | I66: app 2
A67: rev 1 | B67: date 1 | D67: desc 1 | F67: by 1 | G67: chkd 1 | I67: app 1
A68: Rev | B68: Date | D68: Description | F68: By | G68: Checked | I68: Approved
A69: This Calculation represents the work of Worley performed to recognized engineering principles and practices appropriate for the terms of reference provided by Worley contractual Customer. This Calculation is confidential and prepared solely for the use of the Customer. The contents of this Calculation may not be disclosed to or relied upon by any party other than the Customer, and neither Worley, its subconsultants nor their respective employees assume any liability for any reason, including, but not limited to, negligence, to any other party for any information or representation herein.

Sheet Module1

Sheet Checklist
A1: Calculation Checklist
A2: Customer | D2: =customer -> customer name | G2: ='Cover Sheet'!G2 -> Proj No | H2: =Proj_No -> proj no
A3: Project Title | D3: =proj_title -> proj title | G3: ='Cover Sheet'!G3 -> Calc No | H3: KS-PR-CAL-0090
A4: Calculation Title | D4: Vibration Assessment - Surge and Momentum Changes | G4: Phase/CTR | H4: =Phase_CTR -> phase
A5: Elec File Location | D5: =elec_file -> https://worleyparsons-my.sharepoint.com/personal/priyanka_verma_worley_com/Documents/Phase 2 QC2 Document Folder/KS/Calculations KS/Compare/KS-PR-CAL-0090 Vibration Assessment - Surge and Momentum Changes Template.xlsx
G6: Page | H6: 2 | I6: of | J6: =num_pages -> 13
A7: Please check boxes for all applicable items checked or mark as "N/A" if not appropriate:
A8: The objective of this calculation is to determine the main line likelihood of failure (LOF) for vibration induced fatigue due to surge/momentum changes due to valve operation for….
A9: Originator | B9: Checker
C10: Calculation number assigned and registered. refer to project numbering system or Document Number Standard (MS-DP-STD-0009) for format.
C11: All required information on Cover Sheet provided.
C12: Revision history box complete and signed. (Typed names (minimum of first initial and last name e.g. A. Wood) of Originator, Checker, Approver; to be initialed beside at sign-off) (Dates in standard format (DD-MMM-YY)
C13: Table of Contents.
C14: Appropriate stamp for preliminary issues.
C15: Source of input data stated (with revision number and date if relevant).
C16: Customer's requirements included/addressed.
C17: Approach used is appropriate for problem being solved.
C18: Method clear and easy to follow.
C19: Input data correct.
C20: Calculation arithmetically correct OR software previously verified and reference to verification checked.
C21: Calculation result within expected limits.
... C29: Conclusions and recommendations are appropriate.
A30: Checking Records:
C31: Checked and annotated copy of calculation filed (use "Doc Check Print" stamp).
C32: Corrections made as required and calculation dated and signed on cover sheet by checker.
C33: Alternative method calculation and/or representative check performed and filed, as required.
A34: Revisions:
C35: Changes clouded.
C36: Revision history block updated.
C37: Calculation re-checked if required.
A40: =_rev3 -> rev 3 | B40: =date3 -> date 3 | D40: =desc3 -> desc 3 | F40: =orig3 -> by 3 | G40: =_chk3 -> chkd 3 | I40: =_app3 -> app 3
A41: =_rev2 -> rev 2 | B41: =date2 -> date 2 | D41: =desc2 -> desc 2 | F41: =orig2 -> by 2 | G41: =_chk2 -> chkd 2 | I41: =_app2 -> app 2
A42: =_rev1 -> rev 1 | B42: =date1 -> date 1 | D42: =desc1 -> desc 1 | F42: =orig1 -> by 1 | G42: =_chk1 -> chkd 1 | I42: =_app1 -> app 1
A43: Rev | B43: Date | D43: Description | F43: By | G43: Checked | I43: Approved
A44: =disclaimer -> This Calculation represents the work of Worley performed to recognized engineering principles and practices appropriate for the terms of reference provided by Worley contractual Customer. This Calculation is confidential and prepared solely for the use of the Customer. The contents of this Calculation may not be disclosed to or relied upon by any party other than the Customer, and neither Worley, its subconsultants nor their respective employees assume any liability for any reason, including, but not limited to, negligence, to any other party for any information or representation herein.

Sheet ToC
B1: Calculation Sheet
B2: Customer | I2: =customer -> customer name | AA2: ='Cover Sheet'!G2 -> Proj No | AE2: =Proj_No -> proj no
B3: Project Title | I3: =proj_title -> proj title | AA3: ='Cover Sheet'!G3 -> Calc No | AE3: =Calc_No -> KS-PR-CAL-0090
B4: Calculation Title | I4: =calc_title -> Vibration Assessment - Surge and Momentum Changes Template | AA4: Phase/CTR | AE4: =Phase_CTR -> phase
B5: Elec File Location | I5: =elec_file -> https://worleyparsons-my.sharepoint.com/personal/priyanka_verma_worley_com/Documents/Phase 2 QC2 Document Folder/KS/Calculations KS/Compare/KS-PR-CAL-0090 Vibration Assessment - Surge and Momentum Changes Template.xlsx
AD6: Page | AG6: 3 | AJ6: of | AL6: =num_pages -> 13
B7: Rev | D7: Date | G7: By | K7: Checked | O7: Rev | Q7: Date | T7: By | X7: Checked | AB7: Rev | AD7: Date | AG7: By | AK7: Checked
A8: The objective of this calculation is to determine the main line likelihood of failure (LOF) for vibration induced fatigue due to surge/momentum changes due to valve operation for…. | B8: =_rev1 -> rev 1 | D8: =date1 -> date 1 | G8: =orig1 -> by 1 | K8: =_chk1 -> chkd 1 | O8: =_rev2 -> rev 2 | Q8: =date2 -> date 2 | T8: =orig2 -> by 2 | X8: =_chk2 -> chkd 2 | AB8: =_rev3 -> rev 3 | AD8: =date3 -> date 3 | AG8: =orig3 -> by 3 | AK8: =_chk3 -> chkd 3
B12: Table of Contents
AH13: Page
F14: 1.0 | H14: Introduction | AH14: 4
F15: 2.0 | H15: Sketch | AH15: 5
F16: 3.0 | H16: Nomenclature | AH16: 6
F17: 4.0 | H17: Mechanism | AH17: 7
F18: 4.1 | H18: Dry Gas Rapid Valve Opening Methodology | AH18: 7
F19: 4.2 | H19: Liquid or Multiphase Valve Closure | AH19: 8
F20: 4.3 | H20: Liquid or Multiphase Valve Opening | AH20: 9
F21: 5.0 | H21: Case Descriptions | AH21: 10
F22: 6.1 | H22: Case Summary Dry Gas Rapid Valve Opening | AH22: 11
F23: 6.2 | H23: Case Summary Liquid or Multiphase Valve Closure | AH23: 12
F24: 6.3 | H24: Case Summary Liquid or Multiphase Rapid Valve Opening | AH24: 13
B28: Appendices
AH29: Pages
F30: A | H30: ='App A- Dry Gas Calc '!B10 -> APPENDIX - A Dry Gas Rapid Valve Opening | AH30: 1
F31: B | H31: ='AppB- Liquid or Multiphase Calc'!B9 -> APPENDIX - B Liquid Multiphase Valve Closure | AH31: 1
F32: C | H32: APPENDIX - C Liquid Multiphase Valve Opening | AH32: 1
B52: =disclaimer -> This Calculation represents the work of Worley performed to recognized engineering principles and practices appropriate for the terms of reference provided by Worley contractual Customer. This Calculation is confidential and prepared solely for the use of the Customer. The contents of this Calculation may not be disclosed to or relied upon by any party other than the Customer, and neither Worley, its subconsultants nor their respective employees assume any liability for any reason, including, but not limited to, negligence, to any other party for any information or representation herein.

Sheet P4 - Introduction
B1: Calculation Sheet
B2: Customer | I2: =customer -> customer name | AA2: ='Cover Sheet'!G2 -> Proj No | AE2: =Proj_No -> proj no
B3: Project Title | I3: =proj_title -> proj title | AA3: ='Cover Sheet'!G3 -> Calc No | AE3: =Calc_No -> KS-PR-CAL-0090
B4: Calculation Title | I4: =calc_title -> Vibration Assessment - Surge and Momentum Changes Template | AA4: Phase/CTR | AE4: =Phase_CTR -> phase
B5: Elec File Location | I5: =elec_file -> https://worleyparsons-my.sharepoint.com/personal/priyanka_verma_worley_com/Documents/Phase 2 QC2 Document Folder/KS/Calculations KS/Compare/KS-PR-CAL-0090 Vibration Assessment - Surge and Momentum Changes Template.xlsx
AD6: Page | AG6: 4 | AJ6: of | AL6: =num_pages -> 13
B7: Rev | D7: Date | G7: By | K7: Checked | O7: Rev | Q7: Date | T7: By | X7: Checked | AB7: Rev | AD7: Date | AG7: By | AK7: Checked
A8: The objective of this calculation is to determine the main line likelihood of failure (LOF) for vibration induced fatigue due to surge/momentum changes due to valve operation for…. | B8: =_rev1 -> rev 1 | D8: =date1 -> date 1 | G8: =orig1 -> by 1 | K8: =_chk1 -> chkd 1 | O8: =_rev2 -> rev 2 | Q8: =date2 -> date 2 | T8: =orig2 -> by 2 | X8: =_chk2 -> chkd 2 | AB8: =_rev3 -> rev 3 | AD8: =date3 -> date 3 | AG8: =orig3 -> by 3 | AK8: =_chk3 -> chkd 3
C10: =ToC!F14 -> 1.0 | F10: =ToC!H14 -> Introduction
B50: =disclaimer -> This Calculation represents the work of Worley performed to recognized engineering principles and practices appropriate for the terms of reference provided by Worley contractual Customer. This Calculation is confidential and prepared solely for the use of the Customer. The contents of this Calculation may not be disclosed to or relied upon by any party other than the Customer, and neither Worley, its subconsultants nor their respective employees assume any liability for any reason, including, but not limited to, negligence, to any other party for any information or representation herein.

Sheet P5 - Sketch
B1: Calculation Sheet
B2: Customer | I2: =customer -> customer name | AA2: ='Cover Sheet'!G2 -> Proj No | AE2: =Proj_No -> proj no
B3: Project Title | I3: =proj_title -> proj title | AA3: ='Cover Sheet'!G3 -> Calc No | AE3: =Calc_No -> KS-PR-CAL-0090
B4: Calculation Title | I4: =calc_title -> Vibration Assessment - Surge and Momentum Changes Template | AA4: Phase/CTR | AE4: =Phase_CTR -> phase
B5: Elec File Location | I5: =elec_file -> https://worleyparsons-my.sharepoint.com/personal/priyanka_verma_worley_com/Documents/Phase 2 QC2 Document Folder/KS/Calculations KS/Compare/KS-PR-CAL-0090 Vibration Assessment - Surge and Momentum Changes Template.xlsx
AD6: Page | AG6: 5 | AJ6: of | AL6: =num_pages -> 13
B7: Rev | D7: Date | G7: By | K7: Checked | O7: Rev | Q7: Date | T7: By | X7: Checked | AB7: Rev | AD7: Date | AG7: By | AK7: Checked
A8: The objective of this calculation is to determine the main line likelihood of failure (LOF) for vibration induced fatigue due to surge/momentum changes due to valve operation for…. | B8: =_rev1 -> rev 1 | D8: =date1 -> date 1 | G8: =orig1 -> by 1 | K8: =_chk1 -> chkd 1 | O8: =_rev2 -> rev 2 | Q8: =date2 -> date 2 | T8: =orig2 -> by 2 | X8: =_chk2 -> chkd 2 | AB8: =_rev3 -> rev 3 | AD8: =date3 -> date 3 | AG8: =orig3 -> by 3 | AK8: =_chk3 -> chkd 3
C10: =ToC!F15 -> 2.0 | F10: Sketch
B51: =disclaimer -> This Calculation represents the work of Worley performed to recognized engineering principles and practices appropriate for the terms of reference provided by Worley contractual Customer. This Calculation is confidential and prepared solely for the use of the Customer. The contents of this Calculation may not be disclosed to or relied upon by any party other than the Customer, and neither Worley, its subconsultants nor their respective employees assume any liability for any reason, including, but not limited to, negligence, to any other party for any information or representation herein.

Sheet P6-Nomenclature
B1: Calculation Sheet
B2: Customer | I2: =customer -> customer name | AA2: ='Cover Sheet'!G2 -> Proj No | AE2: =Proj_No -> proj no
B3: Project Title | I3: =proj_title -> proj title | AA3: ='Cover Sheet'!G3 -> Calc No | AE3: =Calc_No -> KS-PR-CAL-0090
B4: Calculation Title | I4: =calc_title -> Vibration Assessment - Surge and Momentum Changes Template | AA4: Phase/CTR | AE4: =Phase_CTR -> phase
B5: Elec File Location | I5: =elec_file -> https://worleyparsons-my.sharepoint.com/personal/priyanka_verma_worley_com/Documents/Phase 2 QC2 Document Folder/KS/Calculations KS/Compare/KS-PR-CAL-0090 Vibration Assessment - Surge and Momentum Changes Template.xlsx
AD6: Page | AG6: 6 | AJ6: of | AL6: =num_pages -> 13
B7: Rev | D7: Date | G7: By | K7: Checked | O7: Rev | Q7: Date | T7: By | X7: Checked | AB7: Rev | AD7: Date | AG7: By | AK7: Checked
A8: The objective of this calculation is to determine the main line likelihood of failure (LOF) for vibration induced fatigue due to surge/momentum changes due to valve operation for…. | B8: =_rev1 -> rev 1 | D8: =date1 -> date 1 | G8: =orig1 -> by 1 | K8: =_chk1 -> chkd 1 | O8: =_rev2 -> rev 2 | Q8: =date2 -> date 2 | T8: =orig2 -> by 2 | X8: =_chk2 -> chkd 2 | AB8: =_rev3 -> rev 3 | AD8: =date3 -> date 3 | AG8: =orig3 -> by 3 | AK8: =_chk3 -> chkd 3
C10: =ToC!F16 -> 3.0 | F10: =ToC!H16 -> Nomenclature
C12: c | G12: Speed of sound | AA12: m/s
C13: Dext | G13: External Diameter of Main Line | AA13: mm
C14: Dext | G14: External Diameter of Branch | AA14: mm
C15: Dint | G15: Internal Diameter of Main Line | AA15: mm
C16: Eml | G16: Young Modulus of the main line material | AA16: N/m2
C17: Flim | G17: Limit Force | AA17: kN
C18: Fmax | G18: Peak Force | AA18: kN
C19: K | G19: Fluid bulk modulus | AA19: N/m2
C20: Ldis | G20: Distance between Source and Welded Discontinuity | AA20: m
C21: Lup | G21: Upstream pipe length | AA21: m
C22: Mw | G22: Molecular Weight | AA22: g/mol
C23: P1 | G23: Upstream static Pressure | AA23: Pa(absolute)
... C32: ΔP | G32: Static pressure drop | AA32: Pa
C33: θ | G33: Correction factor for the pipe support
C34: ϒ | G34: Ratio of Specific Heat Capacities (Cp/Cv)
C35: φ | G35: Function defining the flow area as a function of time | AA35: 1/sec
C36: Ψ | G36: Actual pipe wall thickness/Schedule 40 pipe wall thickness
B51: =disclaimer -> This Calculation represents the work of Worley performed to recognized engineering principles and practices appropriate for the terms of reference provided by Worley contractual Customer. This Calculation is confidential and prepared solely for the use of the Customer. The contents of this Calculation may not be disclosed to or relied upon by any party other than the Customer, and neither Worley, its subconsultants nor their respective employees assume any liability for any reason, including, but not limited to, negligence, to any other party for any information or representation herein.

Sheet P7 - Mechanism
B1: Calculation Sheet
B2: Customer | I2: =customer -> customer name | AA2: ='Cover Sheet'!G2 -> Proj No | AE2: =Proj_No -> proj no
B3: Project Title | I3: =proj_title -> proj title | AA3: ='Cover Sheet'!G3 -> Calc No | AE3: =Calc_No -> KS-PR-CAL-0090
B4: Calculation Title | I4: =calc_title -> Vibration Assessment - Surge and Momentum Changes Template | AA4: Phase/CTR | AE4: =Phase_CTR -> phase
B5: Elec File Location | I5: =elec_file -> https://worleyparsons-my.sharepoint.com/personal/priyanka_verma_worley_com/Documents/Phase 2 QC2 Document Folder/KS/Calculations KS/Compare/KS-PR-CAL-0090 Vibration Assessment - Surge and Momentum Changes Template.xlsx
AD6: Page | AG6: 7 | AJ6: of | AL6: =num_pages -> 13
B7: Rev | D7: Date | G7: By | K7: Checked | O7: Rev | Q7: Date | T7: By | X7: Checked | AB7: Rev | AD7: Date | AG7: By | AK7: Checked
A8: The objective of this calculation is to determine the main line likelihood of failure (LOF) for vibration induced fatigue due to surge/momentum changes due to valve operation for…. | B8: =_rev1 -> rev 1 | D8: =date1 -> date 1 | G8: =orig1 -> by 1 | K8: =_chk1 -> chkd 1 | O8: =_rev2 -> rev 2 | Q8: =date2 -> date 2 | T8: =orig2 -> by 2 | X8: =_chk2 -> chkd 2 | AB8: =_rev3 -> rev 3 | AD8: =date3 -> date 3 | AG8: =orig3 -> by 3 | AK8: =_chk3 -> chkd 3
C10: =ToC!F17 -> 4.0 | F10: =ToC!H17 -> Mechanism
C12: As per the the definition given the energy insuite guidelines (Ref. 1) in Surge (or water hammer, as it is commonly
C13: known) is a pressure wave caused by kinetic energy of a fluid in motionwhen it is forced to stop or change direction
C14: suddenly. If the pipe is suddenly closed at the outlet (downstream) a pressure wave is generated which travels back
C15: upstream at the speed of sound in the liquid. This can give rise to high levels of transient pressure and associated
C16: forces acting on the pipework, in liquid and multiphase service.
C18: High transient forces can also be generated by rapid change in fluid momentum caused by the sudden opening of a
C19: valve, e.g. fast operating of a relief valve, in either liquid, multiphase or dry gas service.
C21: =ToC!F18 -> 4.1 | F21: =ToC!H18 -> Dry Gas Rapid Valve Opening Methodology
C23: For a rapid opening of a gas valve the transient forces are due to the sudden change in momentum:
B51: =disclaimer -> This Calculation represents the work of Worley performed to recognized engineering principles and practices appropriate for the terms of reference provided by Worley contractual Customer. This Calculation is confidential and prepared solely for the use of the Customer. The contents of this Calculation may not be disclosed to or relied upon by any party other than the Customer, and neither Worley, its subconsultants nor their respective employees assume any liability for any reason, including, but not limited to, negligence, to any other party for any information or representation herein.

Sheet P8- Liquid or Multiphase
B1: Calculation Sheet
B2: Customer | I2: =customer -> customer name | AA2: ='Cover Sheet'!G2 -> Proj No | AE2: =Proj_No -> proj no
B3: Project Title | I3: =proj_title -> proj title | AA3: ='Cover Sheet'!G3 -> Calc No | AE3: =Calc_No -> KS-PR-CAL-0090
B4: Calculation Title | I4: =calc_title -> Vibration Assessment - Surge and Momentum Changes Template | AA4: Phase/CTR | AE4: =Phase_CTR -> phase
B5: Elec File Location | I5: =elec_file -> https://worleyparsons-my.sharepoint.com/personal/priyanka_verma_worley_com/Documents/Phase 2 QC2 Document Folder/KS/Calculations KS/Compare/KS-PR-CAL-0090 Vibration Assessment - Surge and Momentum Changes Template.xlsx
AD6: Page | AG6: 8 | AJ6: of | AL6: =num_pages -> 13
B7: Rev | D7: Date | G7: By | K7: Checked | O7: Rev | Q7: Date | T7: By | X7: Checked | AB7: Rev | AD7: Date | AG7: By | AK7: Checked
A8: The objective of this calculation is to determine the main line likelihood of failure (LOF) for vibration induced fatigue due to surge/momentum changes due to valve operation for…. | B8: =_rev1 -> rev 1 | D8: =date1 -> date 1 | G8: =orig1 -> by 1 | K8: =_chk1 -> chkd 1 | O8: =_rev2 -> rev 2 | Q8: =date2 -> date 2 | T8: =orig2 -> by 2 | X8: =_chk2 -> chkd 2 | AB8: =_rev3 -> rev 3 | AD8: =date3 -> date 3 | AG8: =orig3 -> by 3 | AK8: =_chk3 -> chkd 3
C10: =ToC!F19 -> 4.2 | F10: =ToC!H19 -> Liquid or Multiphase Valve Closure
C12: The peak pressure surge (Pmax) generated during a valve opening or closure should remain within the design pressure
C13: rating for the line. If this is not the case a detailed surge analysis should be carried out in addition to the following
C14: assesment, please refer to Ref. 1 TM-09.
C16: The intial assesment considers the worst case event of a 'sudden' valve closure, and the effect of the pressure surge
C17: on the pipe. If this is considered acceptable then no further analysis is required as the pressure surge is unlikely to
C18: affect the intergrity of the pipe. Sudden valve closure is defined as a valve closure time that is less than (2Lup/c)
B51: =disclaimer -> This Calculation represents the work of Worley performed to recognized engineering principles and practices appropriate for the terms of reference provided by Worley contractual Customer. This Calculation is confidential and prepared solely for the use of the Customer. The contents of this Calculation may not be disclosed to or relied upon by any party other than the Customer, and neither Worley, its subconsultants nor their respective employees assume any liability for any reason, including, but not limited to, negligence, to any other party for any information or representation herein.

Sheet P 9- Liquid or Multiphase Open
B1: Calculation Sheet
B2: Customer | I2: =customer -> customer name | AA2: ='Cover Sheet'!G2 -> Proj No | AE2: =Proj_No -> proj no
B3: Project Title | I3: =proj_title -> proj title | AA3: ='Cover Sheet'!G3 -> Calc No | AE3: =Calc_No -> KS-PR-CAL-0090
B4: Calculation Title | I4: =calc_title -> Vibration Assessment - Surge and Momentum Changes Template | AA4: Phase/CTR | AE4: =Phase_CTR -> phase
B5: Elec File Location | I5: =elec_file -> https://worleyparsons-my.sharepoint.com/personal/priyanka_verma_worley_com/Documents/Phase 2 QC2 Document Folder/KS/Calculations KS/Compare/KS-PR-CAL-0090 Vibration Assessment - Surge and Momentum Changes Template.xlsx
AD6: Page | AG6: 9 | AJ6: of | AL6: =num_pages -> 13
B7: Rev | D7: Date | G7: By | K7: Checked | O7: Rev | Q7: Date | T7: By | X7: Checked | AB7: Rev | AD7: Date | AG7: By | AK7: Checked
A8: The objective of this calculation is to determine the main line likelihood of failure (LOF) for vibration induced fatigue due to surge/momentum changes due to valve operation for…. | B8: =_rev1 -> rev 1 | D8: =date1 -> date 1 | G8: =orig1 -> by 1 | K8: =_chk1 -> chkd 1 | O8: =_rev2 -> rev 2 | Q8: =date2 -> date 2 | T8: =orig2 -> by 2 | X8: =_chk2 -> chkd 2 | AB8: =_rev3 -> rev 3 | AD8: =date3 -> date 3 | AG8: =orig3 -> by 3 | AK8: =_chk3 -> chkd 3
C10: =ToC!F20 -> 4.3 | F10: =ToC!H20 -> Liquid or Multiphase Valve Opening
C12: High dynamic forces due to the rapid change in momentum, considering the valve opening scenario in a liquid or
C13: multiphase system, is outlined in the steps below. Note: for this case cavitation and flashing needs to be taken into
C14: account using the approach outlined in section T2.9 and T2.10 in Ref. 1 respectively.
B51: =disclaimer -> This Calculation represents the work of Worley performed to recognized engineering principles and practices appropriate for the terms of reference provided by Worley contractual Customer. This Calculation is confidential and prepared solely for the use of the Customer. The contents of this Calculation may not be disclosed to or relied upon by any party other than the Customer, and neither Worley, its subconsultants nor their respective employees assume any liability for any reason, including, but not limited to, negligence, to any other party for any information or representation herein.

Sheet P10- Case Description
B1: Calculation Sheet
B2: Customer | I2: =customer -> customer name | AA2: ='Cover Sheet'!G2 -> Proj No | AE2: =Proj_No -> proj no
B3: Project Title | I3: =proj_title -> proj title | AA3: ='Cover Sheet'!G3 -> Calc No | AE3: =Calc_No -> KS-PR-CAL-0090
B4: Calculation Title | I4: =calc_title -> Vibration Assessment - Surge and Momentum Changes Template | AA4: Phase/CTR | AE4: =Phase_CTR -> phase
B5: Elec File Location | I5: =elec_file -> https://worleyparsons-my.sharepoint.com/personal/priyanka_verma_worley_com/Documents/Phase 2 QC2 Document Folder/KS/Calculations KS/Compare/KS-PR-CAL-0090 Vibration Assessment - Surge and Momentum Changes Template.xlsx
AD6: Page | AG6: 10 | AJ6: of | AL6: =num_pages -> 13
B7: Rev | D7: Date | G7: By | K7: Checked | O7: Rev | Q7: Date | T7: By | X7: Checked | AB7: Rev | AD7: Date | AG7: By | AK7: Checked
A8: The objective of this calculation is to determine the main line likelihood of failure (LOF) for vibration induced fatigue due to surge/momentum changes due to valve operation for…. | B8: =_rev1 -> rev 1 | D8: =date1 -> date 1 | G8: =orig1 -> by 1 | K8: =_chk1 -> chkd 1 | O8: =_rev2 -> rev 2 | Q8: =date2 -> date 2 | T8: =orig2 -> by 2 | X8: =_chk2 -> chkd 2 | AB8: =_rev3 -> rev 3 | AD8: =date3 -> date 3 | AG8: =orig3 -> by 3 | AK8: =_chk3 -> chkd 3
C10: =ToC!F21 -> 5.0 | F10: =ToC!H21 -> Case Descriptions
C12: CASE I User to add description of case CASE II User to add description of case CASE III User to add description of case CASE IV User to add description of case CASE V User to add description of case CASE VI User to add description of case CASE VII User to add description of case CASE VIII User to add description of case CASE IX User to add description of case
B51: =disclaimer -> This Calculation represents the work of Worley performed to recognized engineering principles and practices appropriate for the terms of reference provided by Worley contractual Customer. This Calculation is confidential and prepared solely for the use of the Customer. The contents of this Calculation may not be disclosed to or relied upon by any party other than the Customer, and neither Worley, its subconsultants nor their respective employees assume any liability for any reason, including, but not limited to, negligence, to any other party for any information or representation herein.

Sheet P11-Summary (Dry Gas)
B1: Calculation Sheet
B2: Customer | I2: =customer -> customer name | AA2: ='Cover Sheet'!G2 -> Proj No | AE2: =Proj_No -> proj no
B3: Project Title | I3: =proj_title -> proj title | AA3: ='Cover Sheet'!G3 -> Calc No | AE3: =Calc_No -> KS-PR-CAL-0090
B4: Calculation Title | I4: =calc_title -> Vibration Assessment - Surge and Momentum Changes Template | AA4: Phase/CTR | AE4: =Phase_CTR -> phase
B5: Elec File Location | I5: =elec_file -> https://worleyparsons-my.sharepoint.com/personal/priyanka_verma_worley_com/Documents/Phase 2 QC2 Document Folder/KS/Calculations KS/Compare/KS-PR-CAL-0090 Vibration Assessment - Surge and Momentum Changes Template.xlsx
AD6: Page | AG6: 11 | AJ6: of | AL6: =num_pages -> 13
B7: Rev | D7: Date | G7: By | K7: Checked | O7: Rev | Q7: Date | T7: By | X7: Checked | AB7: Rev | AD7: Date | AG7: By | AK7: Checked
A8: The objective of this calculation is to determine the main line likelihood of failure (LOF) for vibration induced fatigue due to surge/momentum changes due to valve operation for…. | B8: =_rev1 -> rev 1 | D8: =date1 -> date 1 | G8: =orig1 -> by 1 | K8: =_chk1 -> chkd 1 | O8: =_rev2 -> rev 2 | Q8: =date2 -> date 2 | T8: =orig2 -> by 2 | X8: =_chk2 -> chkd 2 | AB8: =_rev3 -> rev 3 | AD8: =date3 -> date 3 | AG8: =orig3 -> by 3 | AK8: =_chk3 -> chkd 3
C10: =ToC!F22 -> 6.1 | F10: =ToC!H22 -> Case Summary Dry Gas Rapid Valve Opening
M12: ='App A- Dry Gas Calc '!T12 -> CASE I | V12: ='App A- Dry Gas Calc '!Z12 -> CASE II | AE12: ='App A- Dry Gas Calc '!AF12 -> CASE III
C13: Input Data
C14: ='App A- Dry Gas Calc '!C14 -> Line/Unit Number | M14: ='App A- Dry Gas Calc '!T14 | V14: ='App A- Dry Gas Calc '!Z14 | AE14: ='App A- Dry Gas Calc '!AF14
C15: ='App A- Dry Gas Calc '!C27 -> Support Type | M15: ='App A- Dry Gas Calc '!T27 -> Medium Stiff | V15: ='App A- Dry Gas Calc '!Z27 -> Medium Stiff | AE15: ='App A- Dry Gas Calc '!AF27 -> Medium Stiff
C16: ='App A- Dry Gas Calc '!C19 -> Nominal Pipe Diameter (mm) | M16: ='App A- Dry Gas Calc '!T19 -> 100 | V16: ='App A- Dry Gas Calc '!Z19 -> 100 | AE16: ='App A- Dry Gas Calc '!AF19 -> 100
C17: Results
C18: Peak Force (kN) Fmax | M18: ='App A- Dry Gas Calc '!T31 -> 6.2856323 | V18: ='App A- Dry Gas Calc '!Z31 -> 6.2856323 | AE18: ='App A- Dry Gas Calc '!AF31 -> 6.2856323
C19: Limit Force (kN) Flim | M19: ='App A- Dry Gas Calc '!T33 -> 1.0613348 | V19: ='App A- Dry Gas Calc '!Z33 -> 1.0613348 | AE19: ='App A- Dry Gas Calc '!AF33 -> 1.3843899
C20: Likelihood of Failure (LOF) | M20: ='App A- Dry Gas Calc '!T34 -> 5.9223844 | V20: ='App A- Dry Gas Calc '!Z34 -> 5.9223844 | AE20: ='App A- Dry Gas Calc '!AF34 -> 4.5403627
B65: =disclaimer -> This Calculation represents the work of Worley performed to recognized engineering principles and practices appropriate for the terms of reference provided by Worley contractual Customer. This Calculation is confidential and prepared solely for the use of the Customer. The contents of this Calculation may not be disclosed to or relied upon by any party other than the Customer, and neither Worley, its subconsultants nor their respective employees assume any liability for any reason, including, but not limited to, negligence, to any other party for any information or representation herein.

Sheet P12-Summary (Valve Closure)
B1: Calculation Sheet
B2: Customer | I2: =customer -> customer name | AA2: ='Cover Sheet'!G2 -> Proj No | AE2: =Proj_No -> proj no
B3: Project Title | I3: =proj_title -> proj title | AA3: ='Cover Sheet'!G3 -> Calc No | AE3: =Calc_No -> KS-PR-CAL-0090
B4: Calculation Title | I4: =calc_title -> Vibration Assessment - Surge and Momentum Changes Template | AA4: Phase/CTR | AE4: =Phase_CTR -> phase
B5: Elec File Location | I5: =elec_file -> https://worleyparsons-my.sharepoint.com/personal/priyanka_verma_worley_com/Documents/Phase 2 QC2 Document Folder/KS/Calculations KS/Compare/KS-PR-CAL-0090 Vibration Assessment - Surge and Momentum Changes Template.xlsx
AD6: Page | AG6: 12 | AJ6: of | AL6: =num_pages -> 13
B7: Rev | D7: Date | G7: By | K7: Checked | O7: Rev | Q7: Date | T7: By | X7: Checked | AB7: Rev | AD7: Date | AG7: By | AK7: Checked
A8: The objective of this calculation is to determine the main line likelihood of failure (LOF) for vibration induced fatigue due to surge/momentum changes due to valve operation for…. | B8: =_rev1 -> rev 1 | D8: =date1 -> date 1 | G8: =orig1 -> by 1 | K8: =_chk1 -> chkd 1 | O8: =_rev2 -> rev 2 | Q8: =date2 -> date 2 | T8: =orig2 -> by 2 | X8: =_chk2 -> chkd 2 | AB8: =_rev3 -> rev 3 | AD8: =date3 -> date 3 | AG8: =orig3 -> by 3 | AK8: =_chk3 -> chkd 3
C10: =ToC!F23 -> 6.2 | F10: =ToC!H23 -> Case Summary Liquid or Multiphase Valve Closure
M12: ='AppB- Liquid or Multiphase Calc'!T11 -> CASE IV | V12: ='AppB- Liquid or Multiphase Calc'!Z11 -> CASE V | AE12: ='AppB- Liquid or Multiphase Calc'!AF11 -> CASE VI
C13: Input Data
C14: ='AppB- Liquid or Multiphase Calc'!C13 -> Line/Unit Number | M14: ='AppB- Liquid or Multiphase Calc'!T13 | V14: ='AppB- Liquid or Multiphase Calc'!Z13 | AE14: ='AppB- Liquid or Multiphase Calc'!AF13
C15: ='AppB- Liquid or Multiphase Calc'!C16 -> Nominal Pipe Diameter (mm) | M15: ='AppB- Liquid or Multiphase Calc'!T16 -> 200 | V15: ='AppB- Liquid or Multiphase Calc'!Z16 -> 200 | AE15: ='AppB- Liquid or Multiphase Calc'!AF16 -> 200
C16: ='AppB- Liquid or Multiphase Calc'!C29 -> Valve Type | M16: ='AppB- Liquid or Multiphase Calc'!T29 -> Butterfly | V16: ='AppB- Liquid or Multiphase Calc'!Z29 -> Gate | AE16: ='AppB- Liquid or Multiphase Calc'!AF29 -> Globe
C17: ='AppB- Liquid or Multiphase Calc'!C24 -> Valve Closing Time (sec) | M17: ='AppB- Liquid or Multiphase Calc'!T24 -> 8 | V17: ='AppB- Liquid or Multiphase Calc'!Z24 -> 8 | AE17: ='AppB- Liquid or Multiphase Calc'!AF24 -> 8
C18: ='AppB- Liquid or Multiphase Calc'!C33 -> Support type | M18: ='AppB- Liquid or Multiphase Calc'!T33 -> Medium Stiff | V18: ='AppB- Liquid or Multiphase Calc'!Z33 -> Medium Stiff | AE18: ='AppB- Liquid or Multiphase Calc'!AF33 -> Medium Stiff
C19: ='AppB- Liquid or Multiphase Calc'!C30 -> Is the Valve downstream of a pump | M19: ='AppB- Liquid or Multiphase Calc'!T30 -> Yes | V19: ='AppB- Liquid or Multiphase Calc'!Z30 -> Yes | AE19: ='AppB- Liquid or Multiphase Calc'!AF30 -> No
C21: Results
C22: Maximum force (kN) Fmax | M22: ='AppB- Liquid or Multiphase Calc'!T42 -> 152.13616 | V22: ='AppB- Liquid or Multiphase Calc'!Z42 -> 152.15977 | AE22: ='AppB- Liquid or Multiphase Calc'!AF42 -> 152.15977
C23: Peak pressure surge (Pa) Psurge | M23: ='AppB- Liquid or Multiphase Calc'!T45 -> 19474.881 | V23: ='AppB- Liquid or Multiphase Calc'!Z45 -> 30643.785 | AE23: ='AppB- Liquid or Multiphase Calc'!AF45 -> 24935.531
C24: Taking into account shut-in of pump Ptotal (Pa) | M24: ='AppB- Liquid or Multiphase Calc'!T46 -> 18469475 | V24: ='AppB- Liquid or Multiphase Calc'!Z46 -> 18480644 | AE24: ='AppB- Liquid or Multiphase Calc'!AF46 -> -
C26: Maximum force (kN) Fmax | M26: ='AppB- Liquid or Multiphase Calc'!T47 -> 0.65160451 | V26: ='AppB- Liquid or Multiphase Calc'!Z47 -> 0.76127572 | AE26: ='AppB- Liquid or Multiphase Calc'!AF47 -> 0.61946704
C27: Limit force (kN) Flim | M27: ='AppB- Liquid or Multiphase Calc'!T49 -> 6.4464187 | V27: ='AppB- Liquid or Multiphase Calc'!Z49 -> 17.495151 | AE27: ='AppB- Liquid or Multiphase Calc'!AF49 -> 17.495151
C28: ='AppB- Liquid or Multiphase Calc'!C50 -> Likelihood of Failure (L.O.F.) | M28: ='AppB- Liquid or Multiphase Calc'!T50 -> 0.10108008 | V28: ='AppB- Liquid or Multiphase Calc'!Z50 -> 0.043513528 | AE28: ='AppB- Liquid or Multiphase Calc'!AF50 -> 0.035407928
B49: =disclaimer -> This Calculation represents the work of Worley performed to recognized engineering principles and practices appropriate for the terms of reference provided by Worley contractual Customer. This Calculation is confidential and prepared solely for the use of the Customer. The contents of this Calculation may not be disclosed to or relied upon by any party other than the Customer, and neither Worley, its subconsultants nor their respective employees assume any liability for any reason, including, but not limited to, negligence, to any other party for any information or representation herein.

Sheet P13-Valve open Liquid multiphas
B1: Calculation Sheet
B2: Customer | I2: =customer -> customer name | AA2: ='Cover Sheet'!G2 -> Proj No | AE2: =Proj_No -> proj no
B3: Project Title | I3: =proj_title -> proj title | AA3: ='Cover Sheet'!G3 -> Calc No | AE3: =Calc_No -> KS-PR-CAL-0090
B4: Calculation Title | I4: =calc_title -> Vibration Assessment - Surge and Momentum Changes Template | AA4: Phase/CTR | AE4: =Phase_CTR -> phase
B5: Elec File Location | I5: =elec_file -> https://worleyparsons-my.sharepoint.com/personal/priyanka_verma_worley_com/Documents/Phase 2 QC2 Document Folder/KS/Calculations KS/Compare/KS-PR-CAL-0090 Vibration Assessment - Surge and Momentum Changes Template.xlsx
AD6: Page | AG6: 13 | AJ6: of | AL6: =num_pages -> 13
B7: Rev | D7: Date | G7: By | K7: Checked | O7: Rev | Q7: Date | T7: By | X7: Checked | AB7: Rev | AD7: Date | AG7: By | AK7: Checked
A8: The objective of this calculation is to determine the main line likelihood of failure (LOF) for vibration induced fatigue due to surge/momentum changes due to valve operation for…. | B8: =_rev1 -> rev 1 | D8: =date1 -> date 1 | G8: =orig1 -> by 1 | K8: =_chk1 -> chkd 1 | O8: =_rev2 -> rev 2 | Q8: =date2 -> date 2 | T8: =orig2 -> by 2 | X8: =_chk2 -> chkd 2 | AB8: =_rev3 -> rev 3 | AD8: =date3 -> date 3 | AG8: =orig3 -> by 3 | AK8: =_chk3 -> chkd 3
C10: =ToC!F24 -> 6.3 | F10: =ToC!H24 -> Case Summary Liquid or Multiphase Rapid Valve Opening
M12: ='APPC- Liquid or Multiphase Open'!T12 -> CASE VII | V12: ='APPC- Liquid or Multiphase Open'!Z12 -> CASE VIII | AE12: ='APPC- Liquid or Multiphase Open'!AF12 -> CASE IX
C13: Input Data
C14: ='APPC- Liquid or Multiphase Open'!C14 -> Line/Unit Number | M14: ='APPC- Liquid or Multiphase Open'!T14 | V14: ='APPC- Liquid or Multiphase Open'!Z14 | AE14: ='APPC- Liquid or Multiphase Open'!AF14
C15: ='APPC- Liquid or Multiphase Open'!C18:S18 -> Nominal Pipe Diameter (mm) | M15: ='APPC- Liquid or Multiphase Open'!T18 -> 80 | V15: ='APPC- Liquid or Multiphase Open'!Z18 -> 80 | AE15: ='APPC- Liquid or Multiphase Open'!AF18 -> 80
C16: ='APPC- Liquid or Multiphase Open'!C26 -> Support Type | M16: ='APPC- Liquid or Multiphase Open'!T26 -> Medium | V16: ='APPC- Liquid or Multiphase Open'!Z26 -> Medium | AE16: ='APPC- Liquid or Multiphase Open'!AF26 -> Medium
C17: Results
C18: Peak Force (kN) Fmax | M18: ='APPC- Liquid or Multiphase Open'!T30 -> 10.793625 | V18: ='APPC- Liquid or Multiphase Open'!Z30 -> 10.793625 | AE18: ='APPC- Liquid or Multiphase Open'!AF30 -> 10.793625
C19: Limit Force (kN) Flim | M19: ='APPC- Liquid or Multiphase Open'!T32 -> 0.3015506 | V19: ='APPC- Liquid or Multiphase Open'!Z32 -> 0.3015506 | AE19: ='APPC- Liquid or Multiphase Open'!AF32 -> 0.3015506
C20: ='APPC- Liquid or Multiphase Open'!C33 -> Likelihood of Failure (L.O.F.) | M20: ='APPC- Liquid or Multiphase Open'!T33 -> 35.793743 | V20: ='APPC- Liquid or Multiphase Open'!Z33 -> 35.793743 | AE20: ='APPC- Liquid or Multiphase Open'!AF33 -> 35.793743
B65: =disclaimer -> This Calculation represents the work of Worley performed to recognized engineering principles and practices appropriate for the terms of reference provided by Worley contractual Customer. This Calculation is confidential and prepared solely for the use of the Customer. The contents of this Calculation may not be disclosed to or relied upon by any party other than the Customer, and neither Worley, its subconsultants nor their respective employees assume any liability for any reason, including, but not limited to, negligence, to any other party for any information or representation herein.

Sheet AppA
B1: Appendix
B2: Customer | I2: =customer -> customer name | AA2: ='Cover Sheet'!G2 -> Proj No | AE2: =Proj_No -> proj no
B3: Project Title | I3: =proj_title -> proj title | AA3: ='Cover Sheet'!G3 -> Calc No | AE3: =Calc_No -> KS-PR-CAL-0090
B4: Calculation Title | I4: =calc_title -> Vibration Assessment - Surge and Momentum Changes Template | AA4: Phase/CTR | AE4: =Phase_CTR -> phase
B5: Elec File Location | I5: =elec_file -> https://worleyparsons-my.sharepoint.com/personal/priyanka_verma_worley_com/Documents/Phase 2 QC2 Document Folder/KS/Calculations KS/Compare/KS-PR-CAL-0090 Vibration Assessment - Surge and Momentum Changes Template.xlsx
AG6: Appendix | AL6: A
B7: Rev | D7: Date | G7: By | K7: Checked | O7: Rev | Q7: Date | T7: By | X7: Checked | AB7: Rev | AD7: Date | AG7: By | AK7: Checked
B8: =_rev1 -> rev 1 | D8: =date1 -> date 1 | G8: =orig1 -> by 1 | K8: =_chk1 -> chkd 1 | O8: =_rev2 -> rev 2 | Q8: =date2 -> date 2 | T8: =orig2 -> by 2 | X8: =_chk2 -> chkd 2 | AB8: =_rev3 -> rev 3 | AD8: =date3 -> date 3 | AG8: =orig3 -> by 3 | AK8: =_chk3 -> chkd 3
B12: ="Appendix "&AL6 -> Appendix A
B13: =VLOOKUP(AL6,ToC!F30:AJ51,3) -> APPENDIX - A Dry Gas Rapid Valve Opening
S14: =VLOOKUP(AL6,ToC!F30:AJ51,29) -> 1 | U14: =IF(S14=1," Page"," Pages") -> Page
B51: =disclaimer -> This Calculation represents the work of Worley performed to recognized engineering principles and practices appropriate for the terms of reference provided by Worley contractual Customer. This Calculation is confidential and prepared solely for the use of the Customer. The contents of this Calculation may not be disclosed to or relied upon by any party other than the Customer, and neither Worley, its subconsultants nor their respective employees assume any liability for any reason, including, but not limited to, negligence, to any other party for any information or representation herein.

Sheet App A- Dry Gas Calc 
B1: Calculation Sheet
B2: Customer | I2: =customer -> customer name | AA2: ='Cover Sheet'!G2 -> Proj No | AE2: =Proj_No -> proj no
B3: Project Title | I3: =proj_title -> proj title | AA3: ='Cover Sheet'!G3 -> Calc No | AE3: =Calc_No -> KS-PR-CAL-0090
B4: Calculation Title | I4: =calc_title -> Vibration Assessment - Surge and Momentum Changes Template | AA4: Phase/CTR | AE4: =Phase_CTR -> phase
B5: Elec File Location | I5: =elec_file -> https://worleyparsons-my.sharepoint.com/personal/priyanka_verma_worley_com/Documents/Phase 2 QC2 Document Folder/KS/Calculations KS/Compare/KS-PR-CAL-0090 Vibration Assessment - Surge and Momentum Changes Template.xlsx
AD6: Page | AG6: 1 | AJ6: of | AL6: =AppA!S14 -> 1
B7: Rev | D7: Date | G7: By | K7: Checked | O7: Rev | Q7: Date | T7: By | X7: Checked | AB7: Rev | AD7: Date | AG7: By | AK7: Checked
A8: The objective of this calculation is to determine the main line likelihood of failure (LOF) for vibration induced fatigue due to surge/momentum changes due to valve operation for…. | B8: =_rev1 -> rev 1 | D8: =date1 -> date 1 | G8: =orig1 -> by 1 | K8: =_chk1 -> chkd 1 | O8: =_rev2 -> rev 2 | Q8: =date2 -> date 2 | T8: =orig2 -> by 2 | X8: =_chk2 -> chkd 2 | AB8: =_rev3 -> rev 3 | AD8: =date3 -> date 3 | AG8: =orig3 -> by 3 | AK8: =_chk3 -> chkd 3
B10: APPENDIX - A Dry Gas Rapid Valve Opening
T12: CASE I | Z12: CASE II | AF12: CASE III
C13: Input Data
C14: Line/Unit Number
C15: Mass Flow Rate (Kg/s) W | T15: 14.86 | Z15: 14.86 | AF15: 14.86
C16: Ratio of Specific Heat Capacities (Cp/Cv) ϒ | T16: 1.33 | Z16: 1.33 | AF16: 1.33
C17: Upstream Temperature (K) Te | T17: 410 | Z17: 410 | AF17: 410
C18: Molecular Weight (g/mol), mW | T18: 21.75 | Z18: 21.75 | AF18: 21.75
C19: Nominal Pipe Diameter (mm) | T19: 100 | Z19: 100 | AF19: 100
C20: Pipe Schedule | T20: Std | Z20: Sch 40 | AF20: Sch 80
C21: External Main Line Diameter (mm) Dext | T21: =IF(T20="Manual Input","-",INDEX($AT$25:$AU$57,MATCH(T19,$AT$25:$AT$57,0),2)) -> 114.3 | Z21: =IF(Z20="Manual Input","-",INDEX($AT$25:$AU$57,MATCH(Z19,$AT$25:$AT$57,0),2)) -> 114.3 | AF21: =IF(AF20="Manual Input","-",INDEX($AT$25:$AU$57,MATCH(AF19,$AT$25:$AT$57,0),2)) -> 114.3
C22: Actual Pipe Wall Thickness (mm) T | T22: =IF(T20="manual Input","-",((INDEX($AV$25:$CK$57, MATCH(T19, $AT$25:$AT$57,0), MATCH(T20,$AV$22:$CK$22, 0)+1))*25.4)) -> 6.0198 | Z22: =IF(Z20="manual Input","-",((INDEX($AV$25:$CK$57, MATCH(Z19, $AT$25:$AT$57,0), MATCH(Z20,$AV$22:$CK$22, 0)+1))*25.4)) -> 6.0198 | AF22: =IF(AF20="manual Input","-",((INDEX($AV$25:$CK$57, MATCH(AF19, $AT$25:$AT$57,0), MATCH(AF20,$AV$22:$CK$22, 0)+1))*25.4)) -> 8.5598 | AR22: Ref | AT22: Size mm | AV22: Sch 5 | AY22: Sch 10 | BB22: Sch 20 | BE22: Sch 30 | BH22: Sch 40 | BK22: Sch 60 | BN22: Sch 80 | BQ22: Sch 100 | BT22: Sch 120 | BW22: Sch 140 | BZ22: Sch 160 | CC22: STD | CF22: XS | CI22: XXS
C23: Manually Enter External Main Line Diameter Dext (mm)
C24: Manually Enter Actual Pipe Wall Thickness (mm) T | AR24: 1 | AT24: Manual Input | AU24: OD | AV24: SCH | AW24: W.T. | AX24: I.D. | AY24: SCH | AZ24: W.T. | BA24: I.D. | BB24: SCH | BC24: W.T. | BD24: I.D. | BE24: SCH | BF24: W.T. | BG24: I.D. | BH24: SCH | BI24: W.T. | BJ24: I.D. | BK24: SCH | BL24: W.T. | BM24: I.D. | BN24: SCH | BO24: W.T. | BP24: I.D. | BQ24: SCH | BR24: W.T. | BS24: I.D. | BT24: SCH | BU24: W.T. | BV24: I.D. | BW24: SCH | BX24: W.T. | BY24: I.D. | BZ24: SCH | CA24: W.T. | CB24: I.D. | CC24: SCH | CD24: W.T. | CE24: I.D. | CF24: SCH | CG24: W.T. | CH24: I.D. | CI24: SCH | CJ24: W.T. | CK24: I.D.
C25: Internal Main Line Diameter (mm) Dint | T25: =IF(T20="Manual Input",(T23-(2*T24)),(T21-(2*T22))) -> 102.2604 | Z25: =IF(Z20="Manual Input",(Z23-(2*Z24)),(Z21-(2*Z22))) -> 102.2604 | AF25: =IF(AF20="Manual Input",(AF23-(2*AF24)),(AF21-(2*AF22))) -> 97.1804 | AR25: 4 | AT25: 10 | AU25: 17.15 | AY25: Sch 10 | AZ25: 0.065 | BA25: 0.545 | BH25: Sch 40 | BI25: 0.091 | BJ25: 0.493 | BN25: Sch 80 | BO25: 0.126 | BP25: 0.425 | CC25: STD | CD25: 0.091 | CE25: 0.493 | CF25: XS | CG25: 0.126 | CH25: 0.423
C26: Schedule 40 Pipe Wall Thickness (mm) | T26: =(INDEX($AT$25:$BI$57,MATCH(T19,$AT$25:$AT$57,0),16))*25.4 -> 6.0198 | Z26: =(INDEX($AT$25:$BI$57,MATCH(Z19,$AT$25:$AT$57,0),16))*25.4 -> 6.0198 | AF26: =(INDEX($AT$25:$BI$57,MATCH(AF19,$AT$25:$AT$57,0),16))*25.4 -> 6.0198 | AR26: 5 | AT26: 15 | AU26: 21.34 | AY26: Sch 10 | AZ26: 0.065 | BA26: 0.674 | BH26: Sch 40 | BI26: 0.109 | BJ26: 0.622 | BN26: Sch 80 | BO26: 0.147 | BP26: 0.546 | BZ26: Sch 160 | CA26: 0.188 | CB26: 0.464 | CC26: STD | CD26: 0.109 | CE26: 0.622 | CF26: XS | CG26: 0.147 | CH26: 0.546 | CI26: XXS | CJ26: 0.294 | CK26: 0.252
C27: Support Type | T27: Medium Stiff | Z27: Medium Stiff | AF27: Medium Stiff | AO27: =IF(Z20="manual input","",(VLOOKUP(Z20,AT25:AU57,2))) -> #N/A | AR27: 6 | AT27: 20 | AU27: 26.67 | AV27: Sch 5 | AW27: 0.065 | AX27: 0.92 | AY27: Sch 10 | AZ27: 0.083 | BA27: 0.884 | BH27: Sch 40 | BI27: 0.113 | BJ27: 0.824 | BN27: Sch 80 | BO27: 0.154 | BP27: 0.742 | BZ27: Sch 160 | CA27: 0.219 | CB27: 0.612 | CC27: STD | CD27: 0.113 | CE27: 0.824 | CF27: XS | CG27: 0.154 | CH27: 0.742 | CI27: XXS | CJ27: 0.308 | CK27: 0.434
C28: Support Correction Factor θ | T28: =IF(T27="user input","",INDEX($AO$33:$AP$36,MATCH(T27,$AP$33:$AP$36,0),1)) -> 2 | Z28: =IF(Z27="user input","",INDEX($AO$33:$AP$36,MATCH(Z27,$AP$33:$AP$36,0),1)) -> 2 | AF28: =IF(AF27="user input","",INDEX($AO$33:$AP$36,MATCH(AF27,$AP$33:$AP$36,0),1)) -> 2 | AR28: 7 | AT28: 25 | AU28: 33.4 | AV28: Sch 5 | AW28: 0.065 | AX28: 1.185 | AY28: Sch 10 | AZ28: 0.109 | BA28: 1.097 | BH28: Sch 40 | BI28: 0.133 | BJ28: 1.049 | BN28: Sch 80 | BO28: 0.179 | BP28: 0.957 | BZ28: Sch 160 | CA28: 0.25 | CB28: 0.815 | CC28: STD | CD28: 0.133 | CE28: 1.049 | CF28: XS | CG28: 0.179 | CH28: 0.957 | CI28: XXS | CJ28: 0.358 | CK28: 0.599
C29: Input Check | T29: =IF(T25<0,"Input Error: Invalid Pipe Wall Thickness",IF(T22=0,"Input Error: Invalid Pipe Schedule","Inputs Ok")) -> Inputs Ok | Z29: =IF(Z25<0,"Input Error: Invalid Pipe Wall Thickness",IF(Z22=0,"Input Error: Invalid Pipe Schedule","Inputs Ok")) -> Inputs Ok | AF29: =IF(AF25<0,"Input Error: Invalid Pipe Wall Thickness",IF(AF22=0,"Input Error: Invalid Pipe Schedule","Inputs Ok")) -> Inputs Ok | AR29: 8 | AT29: 32 | AU29: 42.16 | AV29: Sch 5 | AW29: 0.065 | AX29: 1.53 | AY29: Sch 10 | AZ29: 0.109 | BA29: 1.442 | BH29: Sch 40 | BI29: 0.14 | BJ29: 1.38 | BN29: Sch 80 | BO29: 0.191 | BP29: 1.278 | BZ29: Sch 160 | CA29: 0.25 | CB29: 1.16 | CC29: STD | CD29: 0.14 | CE29: 1.38 | CF29: XS | CG29: 0.191 | CH29: 1.278 | CI29: XXS | CJ29: 0.382 | CK29: 0.896
C30: Calculation | AR30: 9 | AT30: 40 | AU30: 48.26 | AV30: Sch 5 | AW30: 0.065 | AX30: 1.77 | AY30: Sch 10 | AZ30: 0.109 | BA30: 1.682 | BH30: Sch 40 | BI30: 0.145 | BJ30: 1.61 | BN30: Sch 80 | BO30: 0.2 | BP30: 1.5 | BZ30: Sch 160 | CA30: 0.281 | CB30: 1.338 | CC30: STD | CD30: 0.145 | CE30: 1.61 | CF30: XS | CG30: 0.2 | CH30: 1.5 | CI30: XXS | CJ30: 0.4 | CK30: 1.1
C31: Peak Force (kN) Fmax | T31: =IF(T29="Inputs Ok",(T15/1000)*(((2*T16*8314*T17)/((T16+1)*T18))^0.5),"-") -> 6.2856323 | Z31: =IF(Z29="Inputs Ok",(Z15/1000)*(((2*Z16*8314*Z17)/((Z16+1)*Z18))^0.5),"-") -> 6.2856323 | AF31: =IF(AF29="Inputs Ok",(AF15/1000)*(((2*AF16*8314*AF17)/((AF16+1)*AF18))^0.5),"-") -> 6.2856323 | AR31: 10 | AT31: 50 | AU31: 60.33 | AV31: 5 | AW31: 0.065 | AX31: 2.245 | AY31: Sch 10 | AZ31: 0.109 | BA31: 2.157 | BH31: 40 | BI31: 0.154 | BJ31: 2.067 | BN31: 80 | BO31: 0.218 | BP31: 1.939 | BZ31: 160 | CA31: 0.344 | CB31: 1.687 | CC31: STD | CD31: 0.154 | CE31: 2.067 | CF31: XS | CG31: 0.218 | CH31: 1.939 | CI31: XXS | CJ31: 0.436 | CK31: 1.503
C32: Thickness Ratio Ψ | T32: =IF(T29="Inputs OK",(IF(T20="Manual Input",(T24/T26),(T22/T26))),"-") -> 1 | Z32: =IF(Z29="Inputs OK",(IF(Z20="Manual Input",(Z24/Z26),(Z22/Z26))),"-") -> 1 | AF32: =IF(AF29="Inputs OK",(IF(AF20="Manual Input",(AF24/AF26),(AF22/AF26))),"-") -> 1.4219409 | AP32: User Input | AR32: 11 | AT32: 65 | AU32: 73.02 | AV32: Sch 5 | AW32: 0.083 | AX32: 2.709 | AY32: Sch 10 | AZ32: 0.12 | BA32: 2.635 | BH32: Sch 40 | BI32: 0.203 | BJ32: 2.469 | BN32: Sch 80 | BO32: 0.276 | BP32: 2.323 | BZ32: Sch 160 | CA32: 0.375 | CB32: 2.125 | CC32: STD | CD32: 0.203 | CE32: 2.469 | CF32: XS | CG32: 0.276 | CH32: 2.323 | CI32: XXS | CJ32: 0.552 | CK32: 1.771
C33: Limit Force (kN) Flim | T33: =IF(T29="Inputs OK",(IF(T20="Manual Input",((16.8*T32^3)-(1.81*T32^2)+(525*T32)+25.3)*T23*T28*PI()*((T25^2)/(4*10^9)),((16.8*T32^3)-(1.81*T32^2)+(525*T32)+25.3)*T21*T28*PI()*((T25^2)/(4*10^9)))),"-") -> 1.0613348 | Z33: =IF(Z29="Inputs OK",(IF(Z20="Manual Input",((16.8*Z32^3)-(1.81*Z32^2)+(525*Z32)+25.3)*Z23*Z28*PI()*((Z25^2)/(4*10^9)),((16.8*Z32^3)-(1.81*Z32^2)+(525*Z32)+25.3)*Z21*Z28*PI()*((Z25^2)/(4*10^9)))),"-") -> 1.0613348 | AF33: =IF(AF29="Inputs OK",(IF(AF20="Manual Input",((16.8*AF32^3)-(1.81*AF32^2)+(525*AF32)+25.3)*AF23*AF28*PI()*((AF25^2)/(4*10^9)),((16.8*AF32^3)-(1.81*AF32^2)+(525*AF32)+25.3)*AF21*AF28*PI()*((AF25^2)/(4*10^9)))),"-") -> 1.3843899 | AO33: 4 | AP33: Stiff | AR33: 12 | AT33: 80 | AU33: 88.9 | AV33: Sch 5 | AW33: 0.083 | AX33: 3.334 | AY33: Sch 10 | AZ33: 0.12 | BA33: 3.26 | BH33: Sch 40 | BI33: 0.216 | BJ33: 3.068 | BN33: Sch 80 | BO33: 0.3 | BP33: 2.9 | BZ33: Sch 160 | CA33: 0.438 | CB33: 2.624 | CC33: STD | CD33: 0.216 | CE33: 3.068 | CF33: XS | CG33: 0.3 | CH33: 2.9 | CI33: XXS | CJ33: 0.6 | CK33: 2.3
C34: Likelihood of Failure (L.O.F.) | T34: =IF(T29="Inputs Ok",(T31/T33),"Input Error") -> 5.9223844 | Z34: =IF(Z29="Inputs Ok",(Z31/Z33),"Input Error") -> 5.9223844 | AF34: =IF(AF29="Inputs Ok",(AF31/AF33),"Input Error") -> 4.5403627 | AO34: 2 | AP34: Medium Stiff | AR34: 13 | AT34: 90 | AU34: 101.6 | AV34: Sch 5 | AW34: 0.083 | AX34: 3.834 | AY34: Sch 10 | AZ34: 0.12 | BA34: 3.76 | BH34: Sch 40 | BI34: 0.226 | BJ34: 3.548 | BN34: Sch 80 | BO34: 0.318 | BP34: 3.364 | BZ34: Sch 160 | CC34: STD | CD34: 0.226 | CE34: 3.548 | CF34: XS | CG34: 0.318 | CH34: 3.364
AO35: 1 | AP35: Medium | AR35: 14 | AT35: 100 | AU35: 114.3 | AV35: Sch 5 | AW35: 0.083 | AX35: 4.334 | AY35: Sch 10 | AZ35: 0.12 | BA35: 4.26 | BH35: Sch 40 | BI35: 0.237 | BJ35: 4.026 | BN35: Sch 80 | BO35: 0.337 | BP35: 3.826 | BT35: Sch 120 | BU35: 0.438 | BV35: 3.624 | BZ35: Sch 160 | CA35: 0.531 | CB35: 3.438 | CC35: STD | CD35: 0.237 | CE35: 4.026 | CF35: XS | CG35: 0.337 | CH35: 3.826 | CI35: XXS | CJ35: 0.674 | CK35: 3.152
AO36: 0.5 | AP36: Flexible | AR36: 15 | AT36: 125 | AU36: 141.3 | AV36: Sch 5 | AW36: 0.109 | AX36: 5.345 | AY36: Sch 10 | AZ36: 0.134 | BA36: 5.295 | BH36: Sch 40 | BI36: 0.258 | BJ36: 5.047 | BN36: Sch 80 | BO36: 0.375 | BP36: 4.813 | BT36: Sch 120 | BU36: 0.5 | BV36: 4.563 | BZ36: Sch 160 | CA36: 0.625 | CB36: 4.313 | CC36: STD | CD36: 0.258 | CE36: 5.047 | CF36: XS | CG36: 0.375 | CH36: 4.813 | CI36: XXS | CJ36: 0.75 | CK36: 4.063
AR37: 16 | AT37: 150 | AU37: 168.3 | AV37: Sch 5 | AW37: 0.109 | AX37: 6.407 | AY37: Sch 10 | AZ37: 0.134 | BA37: 6.357 | BH37: Sch 40 | BI37: 0.28 | BJ37: 6.065 | BN37: Sch 80 | BO37: 0.432 | BP37: 5.761 | BT37: Sch 120 | BU37: 0.562 | BV37: 5.501 | BZ37: Sch 160 | CA37: 0.719 | CB37: 5.187 | CC37: STD | CD37: 0.28 | CE37: 6.065 | CF37: XS | CG37: 0.432 | CH37: 5.761 | CI37: XXS | CJ37: 0.864 | CK37: 4.897
AR38: 17 | AT38: 200 | AU38: 219.1 | AV38: Sch 5 | AW38: 0.109 | AX38: 8.407 | AY38: Sch 10 | AZ38: 0.148 | BA38: 8.329 | BB38: Sch 20 | BC38: 0.25 | BD38: 8.125 | BE38: Sch 30 | BF38: 0.277 | BG38: 8.071 | BH38: Sch 40 | BI38: 0.322 | BJ38: 7.981 | BK38: Sch 60 | BL38: 0.406 | BM38: 7.813 | BN38: Sch 80 | BO38: 0.5 | BP38: 7.625 | BQ38: Sch 100 | BR38: 0.594 | BS38: 7.437 | BT38: Sch 120 | BU38: 0.719 | BV38: 7.187 | BW38: Sch 140 | BX38: 0.812 | BY38: 7.001 | BZ38: Sch 160 | CA38: 0.906 | CB38: 6.813 | CC38: STD | CD38: 0.322 | CE38: 7.981 | CF38: XS | CG38: 0.5 | CH38: 7.625 | CI38: XXS | CJ38: 0.875 | CK38: 6.875
AR39: 18 | AT39: 250 | AU39: 273.05 | AV39: Sch 5 | AW39: 0.134 | AX39: 10.482 | AY39: Sch 10 | AZ39: 0.165 | BA39: 10.42 | BB39: Sch 20 | BC39: 0.25 | BD39: 10.25 | BE39: Sch 30 | BF39: 0.307 | BG39: 10.136 | BH39: Sch 40 | BI39: 0.365 | BJ39: 10.02 | BK39: Sch 60 | BL39: 0.5 | BM39: 9.75 | BN39: Sch 80 | BO39: 0.594 | BP39: 9.562 | BQ39: Sch 100 | BR39: 0.719 | BS39: 9.312 | BT39: Sch 120 | BU39: 0.844 | BV39: 9.062 | BW39: Sch 140 | BX39: 1 | BY39: 8.75 | BZ39: Sch 160 | CA39: 1.125 | CB39: 8.5 | CC39: STD | CD39: 0.365 | CE39: 10.02 | CF39: XS | CG39: 0.5 | CH39: 9.75 | CI39: XXS | CJ39: 1 | CK39: 8.75
AR40: 19 | AT40: 300 | AU40: 323.85 | AV40: Sch 5 | AW40: 0.156 | AX40: 12.438 | AY40: Sch 10 | AZ40: 0.18 | BA40: 12.39 | BB40: Sch 20 | BC40: 0.25 | BD40: 12.25 | BE40: Sch 30 | BF40: 0.33 | BG40: 12.09 | BH40: Sch 40 | BI40: 0.406 | BJ40: 11.938 | BK40: Sch 60 | BL40: 0.562 | BM40: 11.626 | BN40: Sch 80 | BO40: 0.688 | BP40: 11.374 | BQ40: Sch 100 | BR40: 0.844 | BS40: 11.062 | BT40: Sch 120 | BU40: 1 | BV40: 10.75 | BW40: Sch 140 | BX40: 1.125 | BY40: 10.5 | BZ40: Sch 160 | CA40: 1.312 | CB40: 10.126 | CC40: STD | CD40: 0.375 | CE40: 12 | CF40: XS | CG40: 0.5 | CH40: 11.75 | CI40: XXS | CJ40: 1 | CK40: 10.75
AR41: 20 | AT41: 350 | AU41: 355.6 | AV41: Sch 5 | AW41: 0.156 | AX41: 13.688 | AY41: Sch 10 | AZ41: 0.25 | BA41: 13.5 | BB41: Sch 20 | BC41: 0.312 | BD41: 13.376 | BE41: Sch 30 | BF41: 0.375 | BG41: 13.25 | BH41: Sch 40 | BI41: 0.438 | BJ41: 13.124 | BK41: Sch 60 | BL41: 0.594 | BM41: 12.812 | BN41: Sch 80 | BO41: 0.75 | BP41: 12.5 | BQ41: Sch 100 | BR41: 0.938 | BS41: 12.124 | BT41: Sch 120 | BU41: 1.094 | BV41: 11.812 | BW41: Sch 140 | BX41: 1.25 | BY41: 11.5 | BZ41: Sch 160 | CA41: 1.406 | CB41: 11.188 | CC41: STD | CD41: 0.375 | CE41: 13.25 | CF41: XS | CG41: 0.5 | CH41: 13
AR42: 22 | AT42: 450 | AU42: 457.2 | AV42: Sch 5 | AW42: 0.165 | AX42: 17.67 | AY42: Sch 10 | AZ42: 0.25 | BA42: 17.5 | BB42: Sch 20 | BC42: 0.312 | BD42: 17.376 | BE42: Sch 30 | BF42: 0.438 | BG42: 17.124 | BH42: Sch 40 | BI42: 0.562 | BJ42: 16.876 | BK42: Sch 60 | BL42: 0.75 | BM42: 16.5 | BN42: Sch 80 | BO42: 0.938 | BP42: 16.124 | BQ42: Sch 100 | BR42: 1.156 | BS42: 15.688 | BT42: Sch 120 | BU42: 1.375 | BV42: 15.25 | BW42: Sch 140 | BX42: 1.562 | BY42: 14.876 | BZ42: Sch 160 | CA42: 1.781 | CB42: 14.438 | CC42: STD | CD42: 0.375 | CE42: 17.25 | CF42: XS | CG42: 0.5 | CH42: 17
...

Sheet AppB
B1: Appendix
B2: Customer | I2: =customer -> customer name | AA2: ='Cover Sheet'!G2 -> Proj No | AE2: =Proj_No -> proj no
B3: Project Title | I3: =proj_title -> proj title | AA3: ='Cover Sheet'!G3 -> Calc No | AE3: =Calc_No -> KS-PR-CAL-0090
B4: Calculation Title | I4: =calc_title -> Vibration Assessment - Surge and Momentum Changes Template | AA4: Phase/CTR | AE4: =Phase_CTR -> phase
B5: Elec File Location | I5: =elec_file -> https://worleyparsons-my.sharepoint.com/personal/priyanka_verma_worley_com/Documents/Phase 2 QC2 Document Folder/KS/Calculations KS/Compare/KS-PR-CAL-0090 Vibration Assessment - Surge and Momentum Changes Template.xlsx
AG6: Appendix | AL6: B
B7: Rev | D7: Date | G7: By | K7: Checked | O7: Rev | Q7: Date | T7: By | X7: Checked | AB7: Rev | AD7: Date | AG7: By | AK7: Checked
B8: =_rev1 -> rev 1 | D8: =date1 -> date 1 | G8: =orig1 -> by 1 | K8: =_chk1 -> chkd 1 | O8: =_rev2 -> rev 2 | Q8: =date2 -> date 2 | T8: =orig2 -> by 2 | X8: =_chk2 -> chkd 2 | AB8: =_rev3 -> rev 3 | AD8: =date3 -> date 3 | AG8: =orig3 -> by 3 | AK8: =_chk3 -> chkd 3
B12: ="Appendix "&AL6 -> Appendix B
