Workbook

Sheet Sheet1
B3: Design Pressure calculation for Nozzles | F3: Operating Pressure calculation for Nozzles
B5: Tank height (H) | C5: 26000 | D5: mm | F5: Tank height (H) | H5: mm
B6: Tank Dia (ID) | C6: 29000 | D6: mm | F6: Tank Dia (D) | H6: mm
B7: Design Density (ρ) | C7: 1000 | D7: kg/m^3 | F7: Design Density (ρ) | H7: kg/m^3
B8: Gravity Acceleration | C8: 9.80666 | D8: m/s^2 | F8: Gravity Acceleration | G8: 9.80666 | H8: m/s^2
B9: Tank internal Presssure | C9: 6 | D9: kPa | F9: Tank internal Presssure | H9: kPa
B11: N1 | C11: 24 INCH | F11: =Sheet2!C5 -> N1
B13: Nozzle OD | D13: mm | F13: Nozzle OD | H13: mm
B14: Nozzle location from Top to CL of Nozzle | D14: mm | F14: Nozzle location from Top to CL of Nozzle | H14: mm
B15: Nozzle location from Top to Bottom of Nozzle (h) | C15: =(C14+(C13/2))/1000 -> 0 | D15: m | F15: Nozzle location from Top to Bottom of Nozzle (h) | G15: =(G14+(G13/2))/1000 -> 0 | H15: m
B16: Design Pressure on Nozzle (ρ x G x h) | C16: =(($C$8*$C$7*C15)/1000)+C9 -> 6 | D16: kPa | F16: Design Pressure on Nozzle (ρ x G x h) | G16: =(($G$8*$G$7*G15)/1000)+G9 -> 0 | H16: kPa
C17: =C16*0.001 -> 0.006 | D17: Mpa | G17: =G16*0.001 -> 0 | H17: Mpa
B19: N3 | C19: 10 INCH | E19: N2 | F19: 12 INCH
B21: Nozzle OD | C21: 273.05 | D21: mm | F21: Nozzle OD | G21: =C21 -> 273.05 | H21: mm
B22: Nozzle location from Top to CL of Nozzle | C22: 25450 | D22: mm | F22: Nozzle location from Top to CL of Nozzle | G22: =C22 -> 25450 | H22: mm
B23: Nozzle location from Top to Bottom of Nozzle (h) | C23: =(C22+(C21/2))/1000 -> 25.586525 | D23: m | F23: Nozzle location from Top to Bottom of Nozzle (h) | G23: =(G22+(G21/2))/1000 -> 25.586525 | H23: m
B24: Design Pressure on Nozzle (ρ x G x h) | C24: =(($C$8*$C$7*C23)/1000)+$C$9 -> 256.91835 | D24: kPa | F24: Design Pressure on Nozzle (ρ x G x h) | G24: =(($G$8*$G$7*G23)/1000)+$G$9 -> 0 | H24: kPa
C25: =C24*0.001 -> 0.25691835 | D25: Mpa | G25: =G24*0.001 -> 0 | H25: Mpa
B29: Nozzle OD | D29: mm | F29: Nozzle OD | H29: mm
B30: Nozzle location from Top to CL of Nozzle | D30: mm | F30: Nozzle location from Top to CL of Nozzle | H30: mm
B31: Nozzle location from Top to Bottom of Nozzle (h) | C31: =(C30+(C29/2))/1000 -> 0 | D31: m | F31: Nozzle location from Top to Bottom of Nozzle (h) | G31: =(G30+(G29/2))/1000 -> 0 | H31: m
B32: Design Pressure on Nozzle (ρ x G x h) | C32: =(($C$8*$C$7*C31)/1000)+$C$9 -> 6 | D32: kPa | F32: Design Pressure on Nozzle (ρ x G x h) | G32: =(($G$8*$G$7*G31)/1000)+$G$9 -> 0 | H32: kPa
C33: =C32*0.001 -> 0.006 | D33: Mpa | G33: =G32*0.001 -> 0 | H33: Mpa
A35: N25, | B35: =Sheet2!C9 -> N4 | C35: =Sheet2!D9 -> 24 NPS | F35: =Sheet2!C9 -> N4 | G35: =Sheet2!H9 -> 9.7
B37: Nozzle OD | D37: mm | F37: Nozzle OD | H37: mm
B38: Nozzle location from Top to CL of Nozzle | D38: mm | F38: Nozzle location from Top to CL of Nozzle | H38: mm
B39: Nozzle location from Top to Bottom of Nozzle (h) | C39: =(C38+(C37/2))/1000 -> 0 | D39: m | F39: Nozzle location from Top to Bottom of Nozzle (h) | G39: =(G38+(G37/2))/1000 -> 0 | H39: m
B40: Design Pressure on Nozzle (ρ x G x h) | C40: =(($C$8*$C$7*C39)/1000)+$C$9 -> 6 | D40: kPa | F40: Design Pressure on Nozzle (ρ x G x h) | G40: =(($G$8*$G$7*G39)/1000)+$G$9 -> 0 | H40: kPa
C41: =C40*0.001 -> 0.006 | D41: Mpa | G41: =G40*0.001 -> 0 | H41: Mpa
B43: =Sheet2!C7 -> N10 | C43: =Sheet2!D7 -> 10 NPS | F43: =Sheet2!C10 -> N5 | G43: =Sheet2!H10 -> 9.7
B45: Nozzle OD | D45: mm | F45: Nozzle OD | H45: mm
B46: Nozzle location from Top to CL of Nozzle | D46: mm | F46: Nozzle location from Top to CL of Nozzle | H46: mm
B47: Nozzle location from Top to Bottom of Nozzle (h) | C47: =(C46+(C45/2))/1000 -> 0 | D47: m | F47: Nozzle location from Top to Bottom of Nozzle (h) | G47: =(G46+(G45/2))/1000 -> 0 | H47: m
B48: Design Pressure on Nozzle (ρ x G x h) | C48: =(($C$8*$C$7*C47)/1000)+$C$9 -> 6 | D48: kPa | F48: Design Pressure on Nozzle (ρ x G x h) | G48: =(($G$8*$G$7*G47)/1000)+$G$9 -> 0 | H48: kPa
C49: =C48*0.001 -> 0.006 | D49: Mpa | G49: =G48*0.001 -> 0 | H49: Mpa
A51: N5, | B51: =Sheet2!C11 -> N17 | C51: =Sheet2!D11 -> 3 NPS | E51: N5, | F51: =Sheet2!C11 -> N17 | G51: =Sheet2!H11 -> 9.7
B53: Nozzle OD | D53: mm | F53: Nozzle OD | H53: mm
B54: Nozzle location from Top to CL of Nozzle | D54: mm | F54: Nozzle location from Top to CL of Nozzle | H54: mm
B55: Nozzle location from Top to Bottom of Nozzle (h) | C55: =(C54+(C53/2))/1000 -> 0 | D55: m | F55: Nozzle location from Top to Bottom of Nozzle (h) | G55: =(G54+(G53/2))/1000 -> 0 | H55: m
B56: Design Pressure on Nozzle (ρ x G x h) | C56: =(($C$8*$C$7*C55)/1000)+$C$9 -> 6 | D56: kPa | F56: Design Pressure on Nozzle (ρ x G x h) | G56: =(($G$8*$G$7*G55)/1000)+$G$9 -> 0 | H56: kPa
...

Sheet Sheet3

Sheet Sheet2
B1: Ultra Filtered Water Tank - 710-D-130331
B2: Shell Nozzles
B3: SL.No. | C3: Mark | D3: Nozzle Size | E3: Nozzle Thk (corroded) (mm) | F3: Shell thk (corroded) (mm) | G3: R.F pad OD (mm) | H3: R.F Pad Thk (mm) | I3: Material | K3: As per PIL Input | Q3: Static head | R3: Nozzle Load Status | T3: Remarks | U3: Remarks (updated as per PIL mail dated 27th Feb 2017)
I4: Shell | J4: Nozzle | K4: PR (N) | L4: VL (N) | M4: VC (N) | N4: MT (Nm) | O4: MC (Nm) | P4: ML (Nm) | Q4: MPa | R4: Annex-P | S4: FEA
B5: 1 | C5: N1 | D5: 16 NPS | E5: =16.66-3 -> 13.66 | F5: =9.7-3 -> 6.7 | G5: 850 | H5: 9.7 | I5: A 516 Gr 60N | J5: A 106 Gr BN | K5: 18000 | L5: 18000 | M5: 3000 | N5: 5000 | O5: 3800 | P5: 11000 | Q5: =Sheet1!C17 -> 0.006 | R5: NA | S5: PASS | T5: Due to High Load. PIL to reduce load value. | U5: Pass, by considering ASME Set rule of 2007-2013.
B6: 2 | C6: N26, N29, N31 | D6: 8 NPS | E6: 15.26 | F6: 6.7 | G6: 485 | H6: 9.7 | I6: A 516 Gr 60N | J6: A 106 Gr BN | K6: 5400 | L6: 3500 | M6: 2000 | N6: 3000 | O6: 1300 | P6: 6500 | Q6: =Sheet1!C25 -> 0.25691835 | R6: NA | S6: PASS | T6: Due to High Load. PIL to reduce load value. | U6: Pass, by considering ASME Set rule of 2007-2013.
B7: 3 | C7: N10 | D7: 10 NPS | E7: 15.26 | F7: =9.7-3 -> 6.7 | G7: 585 | H7: 9.7 | I7: A 516 Gr 60N | J7: A 106 Gr BN | K7: 5000 | L7: 7000 | M7: 4000 | N7: 7500 | O7: 2500 | P7: 6000 | Q7: =Sheet1!C49 -> 0.006 | R7: NA | S7: PASS | T7: PIL to provide actual Nozzle load value | U7: Pass.
B8: 4 | C8: N3 | D8: 3 NPS | E8: 8.13 | F8: =9.7-3 -> 6.7 | G8: 265 | H8: 9.7 | I8: A 516 Gr 60N | J8: A 106 Gr BN | K8: 3000 | L8: 3000 | M8: 3000 | N8: 1000 | O8: 900 | P8: 2000 | Q8: =Sheet1!C33 -> 0.006 | R8: NA | S8: PASS | T8: Due to High Load. PIL to reduce load value. | U8: Pass, by considering ASME Set rule of 2007-2013.
B9: 5 | C9: N4 | D9: 24 NPS | E9: 14.48 | F9: =9.7-3 -> 6.7 | G9: 1255 | H9: 9.7 | I9: A 516 Gr 60N | J9: A 106 Gr BN | K9: 24000 | L9: 25000 | M9: 15000 | N9: 15000 | O9: 9500 | P9: 20000 | Q9: =Sheet1!C41 -> 0.006 | R9: NA | S9: PASS | T9: PIL to provide actual Nozzle load value | U9: Pass.
B10: 6 | C10: N5 | D10: 3 NPS | E10: 8.13 | F10: =9.7-3 -> 6.7 | G10: 265 | H10: 9.7 | I10: A 516 Gr 60N | J10: A 106 Gr BN | K10: 2800 | L10: 2800 | M10: 1800 | N10: 1500 | O10: 1000 | P10: 2000 | Q10: =Sheet1!C57 -> 0.006 | R10: NA | S10: PASS | T10: PIL to provide actual Nozzle load value | U10: Pass.
B11: 7 | C11: N17 | D11: 3 NPS | E11: 8.13 | F11: =9.7-3 -> 6.7 | G11: 265 | H11: 9.7 | I11: A 516 Gr 60N | J11: A 106 Gr BN | K11: 3600 | L11: 3600 | M11: 3600 | N11: 810 | O11: 702 | P11: 702 | Q11: =Sheet1!C57 -> 0.006 | R11: NA | S11: PASS | T11: PIL to provide actual Nozzle load value. Mention load value are as per Nozzle Allowable load Specification. | U11: Pass, by considering ASME Set rule of 2007-2013.
B12: 8 | C12: N11 | D12: 4 NPS | E12: 10.49 | F12: =9.7-3 -> 6.7 | G12: 305 | H12: 9.7 | I12: A 516 Gr 60N | J12: A 106 Gr BN | K12: 4800 | L12: 4800 | M12: 4800 | N12: 1440 | O12: 1248 | P12: 1248 | Q12: =Sheet1!C65 -> 0.006 | R12: NA | S12: PASS | U12: Pass, by considering ASME Set rule of 2007-2013.
B13: 9 | C13: N18 | D13: 4 NPS | E13: 10.49 | F13: =9.7-3 -> 6.7 | G13: 305 | H13: 9.7 | I13: A 516 Gr 60N | J13: A 106 Gr BN | K13: 4800 | L13: 4800 | M13: 4800 | N13: 1440 | O13: 1248 | P13: 1248 | Q13: =Sheet1!C65 -> 0.006 | R13: NA | S13: PASS | U13: Pass, by considering ASME Set rule of 2007-2013.
B14: 10 | C14: N6 | D14: 20 NPS | E14: 17.62 | F14: 3 | G14: 1055 | H14: 6 | I14: A 516 Gr 60N | J14: A 106 Gr BN | K14: 6000 | L14: 15000 | M14: 5000 | N14: 6000 | O14: 2500 | P14: 4000 | Q14: =Sheet1!C73 -> 0.006 | R14: NA | S14: PASS | T14: Due to High Load. PIL to reduce load value. | U14: Pass, by considering ASME Set rule of 2007-2013.
B15: 11 | C15: N25 | D15: 24 NPS | E15: 14.48 | F15: =9.7-3 -> 6.7 | G15: 1255 | H15: 9.7 | I15: A 516 Gr 60N | J15: A 106 Gr BN | K15: 20000 | L15: 40000 | M15: 7000 | N15: 7000 | O15: 10000 | P15: 18000 | Q15: =Sheet1!C41 -> 0.006 | R15: NA | S15: PASS | T15: Due to High Load. PIL to reduce load value. | U15: Pass, by considering ASME Set rule of 2007-2013.
B16: 12 | C16: N27 / N32 | D16: 10 NPS | E16: 15.26 | F16: =9.7-3 -> 6.7 | G16: 585 | H16: 9.7 | I16: A 516 Gr 60N | J16: A 106 Gr BN | K16: 5000 | L16: 7000 | M16: 3000 | N16: 3000 | O16: 2200 | P16: 8000 | Q16: =Sheet1!C81 -> 0.006 | R16: NA | S16: PASS | T16: Due to High Load. PIL to reduce load value. | U16: Pass, by considering ASME Set rule of 2007-2013.
B17: 13 | C17: N28 | D17: 18 NPS | E17: 16.05 | F17: =9.7-3 -> 6.7 | G17: 950 | H17: 9.7 | I17: A 516 Gr 60N | J17: A 106 Gr BN | K17: 12000 | L17: 22000 | M17: 8000 | N17: 8000 | O17: 5000 | P17: 14000 | Q17: =Sheet1!C89 -> 0.006 | R17: NA | S17: PASS | T17: Due to High Load. PIL to reduce load value. | U17: Pass, by considering ASME Set rule of 2007-2013.
B18: Roof Nozzles
B19: SL.No. | C19: Mark | D19: Nozzle Size | E19: Nozzle Thk (corroded) (mm) | F19: Roof thk (corroded) (mm) | G19: R.F pad OD (mm) | H19: R.F Pad Thk (mm) | I19: Material | K19: Allowable Nozzle Loads as per Appendix -1 of document no. 15050901-000-00-PI-SPC-0001 Rev.0 | Q19: Internal pressure | R19: Nozzle Load Status (FEA) | T19: Remarks
I20: Roof | J20: Nozzle | K20: PR (N) | L20: VL (N) | M20: VC (N) | N20: MT (Nm) | O20: MC (Nm) | P20: ML (Nm) | Q20: MPa
B21: 1 | C21: N16 | D21: 2 NPS | E21: 7.14 | F21: 5.4 | G21: 175 | H21: 7 | I21: A 516 Gr 60N | J21: A 106 Gr BN | K21: 2400 | L21: 2400 | M21: 2400 | N21: 360 | O21: 312 | P21: 312 | Q21: =Sheet1!C9/1000 -> 0.006 | R21: PASS
B22: 2 | C22: N30 | D22: 12 NPS | E22: 15.88 | F22: 5.4 | G22: 600 | H22: 7 | I22: A 516 Gr 60N | J22: A 106 Gr BN | K22: 8000 | L22: 8000 | M22: 8000 | N22: 6000 | O22: 7000 | P22: 7000 | Q22: 0.00343 | R22: PASS
S35: `
