Workbook

Sheet Flange Leakage
L1: NC-3658.3 FLANGE LEAKAGE CALC
B5: REVISION | F5: 0 | I5: 1 | L5: 2 | O5: 3 | R5: 4 | V5: DOC. NO.: | Z5: FPF1-065A
B6: DATE | I6: 41345 | L6: 41730 | V6: PAGE | Z6: 1
B7: BY | I7: MSV | L7: MSV | V7: JOB NO. ; | Z7: JU 11805 D
B8: CHECK | I8: KK | L8: KK | V8: FOR: | Z8: ITHACA ENERGY | AL8: Data Validation
B9: APPROVED | I9: SB | L9: SB | V9: LOCATION | Z9: STELLA AREA | AL9: ½ | AM9: A1A
AL10: ¾ | AM10: A1B
V11: CALCULATION NO.: | AA11: FPF1-065A-REV2 | AL11: 1 | AM11: A3A
AL12: 1¼ | AM12: A3B
B13: INPUT DATA | AL13: 1½ | AM13: A15A
AL14: 2 | AM14: B1A
AL15: 2½ | AM15: B3A
B16: Piping Material Class | L16: D15C | P16: (Select from list) | AL16: 3 | AM16: B6A
AL17: 3½ | AM17: B6B
B18: Flange size (NB) | L18: 3 | P18: (Select from list) | AL18: 4 | AM18: B9A
AL19: 5 | AM19: B15A
B20: Operating Temperature | L20: 50 | P20: °C | AL20: 6 | AM20: B25A
AL21: 8 | AM21: D1A
B22: Design Temperature | L22: 60 | P22: °C | AL22: 10 | AM22: D3A
AL23: 12 | AM23: D3B
B24: FLANGE DATA | AL24: 14 | AM24: D6A
AL25: 16 | AM25: D6B
AL26: 18 | AM26: D9B
B27: Flange Rating | L27: ='Scratch (2)'!B7 -> 1500# | AL27: 20 | AM27: D15B
AL28: 24 | AM28: D15C
B29: Flange Material | L29: ='Scratch (2)'!B6 -> A350 Gr LF2 Cl 1 | AM29: D25B
AM30: G1C
B31: Material Group | L31: ='Scratch (2)'!B8 -> 1.1 | AM31: S1A
AM32: S1B
B33: Number of Bolts | L33: ='Scratch (2)'!B12 -> 8 | AM33: S1C
AM34: S1D
B35: Bolt Diameter. | L35: ='Scratch (2)'!B13 -> 1.125 | AM35: S3A
AM36: S3B
B37: CAESAR II INPUT | AM37: S3C
AM38: S6A
AM39: S6B
B40: Bolt Area | I40: Ab | L40: ='Scratch (2)'!B16 -> 3576.767 | P40: mm² | AM40: S9A
AM41: S15A
B42: Bolt Circle Diameter | I42: C | L42: ='Scratch (2)'!B11 -> 203.2 | P42: mm | AM42: S25A
AM43: S25B
...

Sheet NC-3658.3
B2: Ithaca - FPF1 Project | BA2: Data Validation
BA3: ½ | BB3: A1A
B4: Allowable Flange Bending Moment Calculation to NC-3658.3 | BA4: ¾ | BB4: A1B
BA5: 1 | BB5: A3A
B6: Refer to ASME Section III, Division 1 - NC (2009b) | BA6: 1¼ | BB6: A3B
BA7: 1½ | BB7: A15A
BA8: 2 | BB8: B1A
B9: Stress Calculation No | R9: Analyst | AB9: Date | BA9: 2½ | BB9: B3A
BA10: 3 | BB10: B6A
B11: Revision | R11: Checker | AB11: Date | BA11: 3½ | BB11: B6B
BA12: 4 | BB12: B9A
BA13: 5 | BB13: B15A
B14: Flange NPS | H14: 12 | N14: Piping Material Class | T14: S25B | Z14: Design Temperature | AF14: 200 | BA14: 6 | BB14: B25A
BA15: 8 | BB15: D1A
BA16: 10 | BB16: D3A
B17: Flange Material | H17: =Scratch!B6 -> A182 F53 UNS S32750 | N17: Flange Material Group | T17: =Scratch!B8 -> 2.8 | Z17: Flange Rating | AF17: =Scratch!B7 -> 2500# | BA17: 12 | BB17: D3B
BA18: 14 | BB18: D6A
B19: Bolt Circle Diameter | H19: =Scratch!B11 -> 619.1 | N19: No. Bolts | T19: =Scratch!B12 -> 12 | Z19: Bolt Diameter | AF19: =Scratch!B13 -> 2.75 | BA19: 16 | BB19: D6B
BA20: 18 | BB20: D9B
B21: Yield Strength at Ambient Temperature and Below | T21: =Scratch!B18 -> 552 | Z21: Total Bolt Area | AF21: =Scratch!B16 -> 35767.67 | BA21: 20 | BB21: D15B
BA22: 24 | BB22: D15C
B23: Yield Strength at Maximum Design Temperature | T23: =Scratch!B28 -> 420 | Z23: Flange Material Factor | AF23: =Scratch!B31 -> 1 | BB23: D25B
BB24: G1C
BB25: S1A
B26: Maximum Allowable Bending Moment Mfs at Max Design Temperature | Z26: =Scratch!B34 -> 480519.69 | BB26: S1B
BB27: S1C
BB28: S1D
B29: =Scratch!B37 | BB29: S3A
BB30: S3B
BB31: S3C
BB32: S6A
BB33: S6B
BB34: S9A
BB35: S15A
BB36: S25A
BB37: S25B
BB38: S100B
BB39: T1A
BB40: X1A

Sheet Scratch
I1: -200 | J1: 0
A2: Flange Size | B2: ='NC-3658.3'!H14 -> 12 | F2: 150# | G2: 0 | I2: -30 | J2: 1
A3: Spec | B3: ='NC-3658.3'!T14 -> S25B | F3: 300# | G3: 3 | I3: 40 | J3: 2
A4: Temperature | B4: ='NC-3658.3'!AF14 -> 200 | F4: 600# | G4: 6 | I4: 65 | J4: 3
F5: 900# | G5: 9 | I5: 100 | J5: 4
A6: Material | B6: =VLOOKUP(B3,'Spec Data'!A2:B39,2,FALSE) -> A182 F53 UNS S32750 | F6: 1500# | G6: 12 | I6: 125 | J6: 5
A7: Rating | B7: =VLOOKUP(B3,'Spec Data'!A2:C39,3,FALSE) -> 2500# | F7: 2500# | G7: 15 | I7: 150 | J7: 6
A8: Material Group | B8: =VLOOKUP(B3,'Spec Data'!A2:E39,5,FALSE) -> 2.8 | I8: 175 | J8: 7
I9: 200 | J9: 8
A10: Offset | B10: =VLOOKUP(B7,F2:G7,2,FALSE) -> 15 | I10: 225 | J10: 9
A11: W | B11: =VLOOKUP(B2,'Flange Data'!A4:S23,B10+2,FALSE) -> 619.1 | I11: 250 | J11: 10
A12: No. Bolts | B12: =VLOOKUP(B2,'Flange Data'!A4:S23,B10+3,FALSE) -> 12 | I12: 275 | J12: 11
A13: Bolt Dia | B13: =VLOOKUP(B2,'Flange Data'!A4:S23,B10+4,FALSE) -> 2.75 | I13: 300 | J13: 12
I14: 325 | J14: 13
A15: Bolt Area | B15: =VLOOKUP(B13,'Bolt Data'!A4:C27,3,FALSE) -> 2980.6392 | I15: 350 | J15: 14
A16: Total Bolt Area | B16: =B15*B12 -> 35767.67 | I16: 375 | J16: 15
I17: 400 | J17: 16
A18: Yield at Ambient | B18: =VLOOKUP(B6,'Material Data'!A3:V8,2,FALSE) -> 552 | I18: 425 | J18: 17
I19: 450 | J19: 18
A20: Yield Temp Pos 1 | B20: =VLOOKUP(B4,I1:J22,2,TRUE) -> 8 | I20: 475 | J20: 19
A21: Yield Temp Pos 2 | B21: =B20+1 -> 9 | I21: 500 | J21: 20
A22: Base Yield Temp | B22: =OFFSET(I1,B20,0) -> 200 | I22: 525 | J22: 21
A23: Gap | B23: =B4-B22 -> 0
A24: Difference | B24: =OFFSET(I1,B21,0)-OFFSET(I1,B20,0) -> 25
A26: Yield 1 | B26: =VLOOKUP(B6,'Material Data'!A3:V8,B20+1,FALSE) -> 420
A27: Yield 2 | B27: =VLOOKUP(B6,'Material Data'!A3:V8,B21+1,FALSE) -> 411
A28: Interpolated Yield | B28: =IF(B20=0,B27,B26-(B23/B24)*(B26-B27)) -> 420
A30: Yield/250 | B30: =B28/250 -> 1.68
A31: Material Factor | B31: =IF(B30>1,1,B30) -> 1
A33: Allowable Nmm | B33: =21.7*B31*B11*B16 -> 4.8051969e+08
A34: Allowable Nm | B34: =B33/1000 -> 480519.69
A36: Note | B36: =VLOOKUP(B3,'Spec Data'!A2:D39,4,FALSE) -> 0
A37: Nota | B37: =IF(B36>0,B36,"")

Sheet Scratch (2)
I1: -200 | J1: 0
A2: Flange Size | B2: ='Flange Leakage'!L18 -> 3 | F2: 150# | G2: 0 | I2: -30 | J2: 1
A3: Spec | B3: ='Flange Leakage'!L16 -> D15C | F3: 300# | G3: 3 | I3: 40 | J3: 2
A4: Temperature | B4: ='Flange Leakage'!L20 -> 50 | F4: 600# | G4: 6 | I4: 65 | J4: 3
F5: 900# | G5: 9 | I5: 100 | J5: 4
A6: Material | B6: =VLOOKUP(B3,'Spec Data'!A2:B39,2,FALSE) -> A350 Gr LF2 Cl 1 | F6: 1500# | G6: 12 | I6: 125 | J6: 5
A7: Rating | B7: =VLOOKUP(B3,'Spec Data'!A2:C39,3,FALSE) -> 1500# | F7: 2500# | G7: 15 | I7: 150 | J7: 6
A8: Material Group | B8: =VLOOKUP(B3,'Spec Data'!A2:E39,5,FALSE) -> 1.1 | I8: 175 | J8: 7
I9: 200 | J9: 8
A10: Offset | B10: =VLOOKUP(B7,F2:G7,2,FALSE) -> 12 | I10: 225 | J10: 9
A11: W | B11: =VLOOKUP(B2,'Flange Data'!A4:S23,B10+2,FALSE) -> 203.2 | I11: 250 | J11: 10
A12: No. Bolts | B12: =VLOOKUP(B2,'Flange Data'!A4:S23,B10+3,FALSE) -> 8 | I12: 275 | J12: 11
A13: Bolt Dia | B13: =VLOOKUP(B2,'Flange Data'!A4:S23,B10+4,FALSE) -> 1.125 | I13: 300 | J13: 12
I14: 325 | J14: 13
A15: Bolt Area | B15: =VLOOKUP(B13,'Bolt Data'!A4:C27,3,FALSE) -> 447.09588 | I15: 350 | J15: 14
A16: Total Bolt Area | B16: =B15*B12 -> 3576.767 | I16: 375 | J16: 15
I17: 400 | J17: 16
A18: Yield at Ambient | B18: =VLOOKUP(B6,'Material Data'!A3:V8,2,FALSE) -> 248 | I18: 425 | J18: 17
I19: 450 | J19: 18
A20: Yield Temp Pos 1 | B20: =VLOOKUP(B4,I1:J22,2,TRUE) -> 2 | I20: 475 | J20: 19
A21: Yield Temp Pos 2 | B21: =B20+1 -> 3 | I21: 500 | J21: 20
A22: Base Yield Temp | B22: =OFFSET(I1,B20,0) -> 40 | I22: 525 | J22: 21
A23: Gap | B23: =B4-B22 -> 10
A24: Difference | B24: =OFFSET(I1,B21,0)-OFFSET(I1,B20,0) -> 25
A26: Yield 1 | B26: =VLOOKUP(B6,'Material Data'!A3:V8,B20+1,FALSE) -> 248
A27: Yield 2 | B27: =VLOOKUP(B6,'Material Data'!A3:V8,B21+1,FALSE) -> 233
A28: Interpolated Yield | B28: =IF(B20=0,B27,B26-(B23/B24)*(B26-B27)) -> 242
A30: Yield/250 | B30: =B28/250 -> 0.968
A31: Material Factor | B31: =IF(B30>1,1,B30) -> 0.968
A33: Allowable Nmm | B33: =21.7*B31*B11*B16 -> 15266850
A34: Allowable Nm | B34: =B33/1000 -> 15266.85
A36: Note | B36: =VLOOKUP(B3,'Spec Data'!A2:D39,4,FALSE) -> 0
A37: Nota | B37: =IF(B36>0,B36,"")

Sheet Scratch (2a)
I1: -200 | J1: 0
A2: Flange Size | B2: ='Flange Leakage'!L18 -> 3 | F2: 150# | G2: 0 | I2: -30 | J2: 1
A3: Spec | B3: ='Flange Leakage'!L16 -> D15C | F3: 300# | G3: 3 | I3: 40 | J3: 2
A4: Temperature | B4: ='Flange Leakage'!L22 -> 60 | F4: 600# | G4: 6 | I4: 65 | J4: 3
F5: 900# | G5: 9 | I5: 100 | J5: 4
A6: Material | B6: =VLOOKUP(B3,'Spec Data'!A2:B39,2,FALSE) -> A350 Gr LF2 Cl 1 | F6: 1500# | G6: 12 | I6: 125 | J6: 5
A7: Rating | B7: =VLOOKUP(B3,'Spec Data'!A2:C39,3,FALSE) -> 1500# | F7: 2500# | G7: 15 | I7: 150 | J7: 6
A8: Material Group | B8: =VLOOKUP(B3,'Spec Data'!A2:E39,5,FALSE) -> 1.1 | I8: 175 | J8: 7
I9: 200 | J9: 8
A10: Offset | B10: =VLOOKUP(B7,F2:G7,2,FALSE) -> 12 | I10: 225 | J10: 9
A11: W | B11: =VLOOKUP(B2,'Flange Data'!A4:S23,B10+2,FALSE) -> 203.2 | I11: 250 | J11: 10
A12: No. Bolts | B12: =VLOOKUP(B2,'Flange Data'!A4:S23,B10+3,FALSE) -> 8 | I12: 275 | J12: 11
A13: Bolt Dia | B13: =VLOOKUP(B2,'Flange Data'!A4:S23,B10+4,FALSE) -> 1.125 | I13: 300 | J13: 12
I14: 325 | J14: 13
A15: Bolt Area | B15: =VLOOKUP(B13,'Bolt Data'!A4:C27,3,FALSE) -> 447.09588 | I15: 350 | J15: 14
A16: Total Bolt Area | B16: =B15*B12 -> 3576.767 | I16: 375 | J16: 15
I17: 400 | J17: 16
A18: Yield at Ambient | B18: =VLOOKUP(B6,'Material Data'!A3:V8,2,FALSE) -> 248 | I18: 425 | J18: 17
I19: 450 | J19: 18
A20: Yield Temp Pos 1 | B20: =VLOOKUP(B4,I1:J22,2,TRUE) -> 2 | I20: 475 | J20: 19
A21: Yield Temp Pos 2 | B21: =B20+1 -> 3 | I21: 500 | J21: 20
A22: Base Yield Temp | B22: =OFFSET(I1,B20,0) -> 40 | I22: 525 | J22: 21
A23: Gap | B23: =B4-B22 -> 20
A24: Difference | B24: =OFFSET(I1,B21,0)-OFFSET(I1,B20,0) -> 25
A26: Yield 1 | B26: =VLOOKUP(B6,'Material Data'!A3:V8,B20+1,FALSE) -> 248
A27: Yield 2 | B27: =VLOOKUP(B6,'Material Data'!A3:V8,B21+1,FALSE) -> 233
A28: Interpolated Yield | B28: =IF(B20=0,B27,B26-(B23/B24)*(B26-B27)) -> 236
A30: Yield/250 | B30: =B28/250 -> 0.944
A31: Material Factor | B31: =IF(B30>1,1,B30) -> 0.944
A33: Allowable Nmm | B33: =21.7*B31*B11*B16 -> 14888333
A34: Allowable Nm | B34: =B33/1000 -> 14888.333
A36: Note | B36: =VLOOKUP(B3,'Spec Data'!A2:D39,4,FALSE) -> 0
A37: Nota | B37: =IF(B36>0,B36,"")

Sheet Flange Data
B1: 150# | E1: 300# | H1: 600# | K1: 900# | N1: 1500# | Q1: 2500#
B2: Bolt Circle Diameter | C2: No. Bolts | D2: Bolt Dia | E2: Bolt Circle Diameter | F2: No. Bolts | G2: Bolt Dia | H2: Bolt Circle Diameter | I2: No. Bolts | J2: Bolt Dia | K2: Bolt Circle Diameter | L2: No. Bolts | M2: Bolt Dia | N2: Bolt Circle Diameter | O2: No. Bolts | P2: Bolt Dia | Q2: Bolt Circle Diameter | R2: No. Bolts | S2: Bolt Dia
A3: NPS | B3: W - mm | D3: In | E3: W - mm | G3: In | H3: W - mm | J3: In | K3: W - mm | M3: In | N3: W - mm | P3: In | Q3: W - mm | S3: In
A4: ½ | B4: 60.3 | C4: 4 | D4: =1/2 -> 0.5 | E4: 66.7 | F4: 4 | G4: 0.5 | H4: 66.7 | I4: 4 | J4: 0.5 | K4: 82.6 | L4: 4 | M4: 0.75 | N4: 82.6 | O4: 4 | P4: 0.75 | Q4: 88.9 | R4: 4 | S4: 0.75
A5: ¾ | B5: 69.9 | C5: 4 | D5: =1/2 -> 0.5 | E5: 82.6 | F5: 4 | G5: =5/8 -> 0.625 | H5: 82.6 | I5: 4 | J5: =5/8 -> 0.625 | K5: 88.9 | L5: 4 | M5: 0.75 | N5: 88.9 | O5: 4 | P5: 0.75 | Q5: 95.2 | R5: 4 | S5: 0.75
A6: 1 | B6: 79.4 | C6: 4 | D6: =1/2 -> 0.5 | E6: 88.9 | F6: 4 | G6: =5/8 -> 0.625 | H6: 88.9 | I6: 4 | J6: =5/8 -> 0.625 | K6: 101.6 | L6: 4 | M6: 0.875 | N6: 101.6 | O6: 4 | P6: 0.875 | Q6: 108 | R6: 4 | S6: 0.875
A7: 1¼ | B7: 88.9 | C7: 4 | D7: =1/2 -> 0.5 | E7: 98.4 | F7: 4 | G7: =5/8 -> 0.625 | H7: 98.4 | I7: 4 | J7: =5/8 -> 0.625 | K7: 111.1 | L7: 4 | M7: 0.875 | N7: 111.1 | O7: 4 | P7: 0.875 | Q7: 130.2 | R7: 4 | S7: 1
A8: 1½ | B8: 98.4 | C8: 4 | D8: =1/2 -> 0.5 | E8: 114.3 | F8: 4 | G8: 0.75 | H8: 114.3 | I8: 4 | J8: 0.75 | K8: 123.8 | L8: 4 | M8: 1 | N8: 123.8 | O8: 4 | P8: 1 | Q8: 146 | R8: 4 | S8: 1.125
A9: 2 | B9: 120.7 | C9: 4 | D9: =5/8 -> 0.625 | E9: 127 | F9: 8 | G9: 0.625 | H9: 127 | I9: 8 | J9: 0.625 | K9: 165.1 | L9: 8 | M9: 0.875 | N9: 165.1 | O9: 8 | P9: 0.875 | Q9: 171.4 | R9: 8 | S9: 1
A10: 2½ | B10: 139.7 | C10: 4 | D10: =5/8 -> 0.625 | E10: 149.2 | F10: 8 | G10: 0.75 | H10: 149.2 | I10: 8 | J10: 0.75 | K10: 190.5 | L10: 8 | M10: 1 | N10: 190.5 | O10: 8 | P10: 1 | Q10: 196.8 | R10: 8 | S10: 1.125
A11: 3 | B11: 152.4 | C11: 4 | D11: =5/8 -> 0.625 | E11: 168.3 | F11: 8 | G11: 0.75 | H11: 168.3 | I11: 8 | J11: 0.75 | K11: 190.5 | L11: 8 | M11: 0.875 | N11: 203.2 | O11: 8 | P11: 1.125 | Q11: 228.6 | R11: 8 | S11: 1.25
A12: 3½ | B12: 177.8 | C12: 8 | D12: =5/8 -> 0.625 | E12: 184.2 | F12: 8 | G12: 0.75 | H12: 184.2 | I12: 8 | J12: 0.875
A13: 4 | B13: 190.5 | C13: 8 | D13: =5/8 -> 0.625 | E13: 200 | F13: 8 | G13: 0.75 | H13: 215.9 | I13: 8 | J13: 0.875 | K13: 235 | L13: 8 | M13: 1.125 | N13: 241.3 | O13: 8 | P13: 1.25 | Q13: 273 | R13: 8 | S13: 1.5
A14: 5 | B14: 215.9 | C14: 8 | D14: =3/4 -> 0.75 | E14: 235 | F14: 8 | G14: 0.75 | H14: 266.7 | I14: 8 | J14: 1 | K14: 279.4 | L14: 8 | M14: 1.25 | N14: 292.1 | O14: 8 | P14: 1.5 | Q14: 323.8 | R14: 8 | S14: 1.75
A15: 6 | B15: 241.3 | C15: 8 | D15: =3/4 -> 0.75 | E15: 269.9 | F15: 12 | G15: 0.75 | H15: 292.1 | I15: 12 | J15: 1 | K15: 317.5 | L15: 12 | M15: 1.125 | N15: 317.5 | O15: 12 | P15: 1.375 | Q15: 368.3 | R15: 8 | S15: 2
A16: 8 | B16: 298.5 | C16: 8 | D16: =3/4 -> 0.75 | E16: 330.2 | F16: 12 | G16: =7/8 -> 0.875 | H16: 349.2 | I16: 12 | J16: 1.125 | K16: 393.7 | L16: 12 | M16: 1.375 | N16: 393.7 | O16: 12 | P16: 1.625 | Q16: 438.2 | R16: 12 | S16: 2
A17: 10 | B17: 362 | C17: 12 | D17: =7/8 -> 0.875 | E17: 387.4 | F17: 16 | G17: 1 | H17: 431.8 | I17: 16 | J17: 1.25 | K17: 469.9 | L17: 16 | M17: 1.375 | N17: 482.6 | O17: 12 | P17: 1.875 | Q17: 539.8 | R17: 12 | S17: 2.5
A18: 12 | B18: 431.8 | C18: 12 | D18: =7/8 -> 0.875 | E18: 450.8 | F18: 16 | G18: 1.125 | H18: 489 | I18: 20 | J18: 1.25 | K18: 533.4 | L18: 20 | M18: 1.375 | N18: 571.5 | O18: 16 | P18: 2 | Q18: 619.1 | R18: 12 | S18: 2.75
A19: 14 | B19: 476.3 | C19: 12 | D19: 1 | E19: 514.4 | F19: 20 | G19: 1.125 | H19: 527 | I19: 20 | J19: =11/8 -> 1.375 | K19: 558.8 | L19: 20 | M19: 1.5 | N19: 635 | O19: 16 | P19: 2.25
A20: 16 | B20: 539.8 | C20: 16 | D20: 1 | E20: 571.5 | F20: 20 | G20: 1.25 | H20: 603 | I20: 20 | J20: 1.5 | K20: 616 | L20: 20 | M20: 1.625 | N20: 704.8 | O20: 16 | P20: 2.5
A21: 18 | B21: 577.9 | C21: 16 | D21: 1.125 | E21: 628.6 | F21: 24 | G21: 1.25 | H21: 654 | I21: 20 | J21: =13/8 -> 1.625 | K21: 685.8 | L21: 20 | M21: 1.875 | N21: 774.7 | O21: 16 | P21: 2.75
A22: 20 | B22: 635 | C22: 20 | D22: 1.125 | E22: 685.8 | F22: 24 | G22: 1.25 | H22: 723.9 | I22: 24 | J22: =13/8 -> 1.625 | K22: 749.8 | L22: 20 | M22: 2 | N22: 831.8 | O22: 16 | P22: 3
A23: 24 | B23: 749.3 | C23: 20 | D23: 1.25 | E23: 812.8 | F23: 24 | G23: 1.5 | H23: 838.2 | I23: 24 | J23: =15/8 -> 1.875 | K23: 901.7 | L23: 20 | M23: 2.5 | N23: 990.6 | O23: 16 | P23: 3.5
A27: B16.5 2009

Sheet Bolt Data
A1: UNC Bolts
A2: Nominal Size | B2: Section at Minor Diameter
A3: in | B3: sq in | C3: sq mm
A4: 0.25 | B4: 0.0269 | C4: =B4*(25.4^2) -> 17.354804
A5: =5/16 -> 0.3125 | B5: 0.0454 | C5: =B5*(25.4^2) -> 29.290264
A6: =3/8 -> 0.375 | B6: 0.0678 | C6: =B6*(25.4^2) -> 43.741848
A7: =7/16 -> 0.4375 | B7: 0.0933 | C7: =B7*(25.4^2) -> 60.193428
A8: =1/2 -> 0.5 | B8: 0.1257 | C8: =B8*(25.4^2) -> 81.096612
A9: =9/16 -> 0.5625 | B9: 0.162 | C9: =B9*(25.4^2) -> 104.51592
A10: =5/8 -> 0.625 | B10: 0.202 | C10: =B10*(25.4^2) -> 130.32232
A11: =3/4 -> 0.75 | B11: 0.302 | C11: =B11*(25.4^2) -> 194.83832
A12: =7/8 -> 0.875 | B12: 0.419 | C12: =B12*(25.4^2) -> 270.32204
A13: 1 | B13: 0.551 | C13: =B13*(25.4^2) -> 355.48316
A14: =9/8 -> 1.125 | B14: 0.693 | C14: =B14*(25.4^2) -> 447.09588
A15: =1.25 -> 1.25 | B15: 0.89 | C15: =B15*(25.4^2) -> 574.1924
A16: =11/8 -> 1.375 | B16: 1.054 | C16: =B16*(25.4^2) -> 679.99864
A17: 1.5 | B17: 1.294 | C17: =B17*(25.4^2) -> 834.83704
A18: 1.75 | B18: 1.74 | C18: =B18*(25.4^2) -> 1122.5784
A19: 2 | B19: 2.3 | C19: =B19*(25.4^2) -> 1483.868
A20: 2.25 | B20: 3.02 | C20: =B20*(25.4^2) -> 1948.3832
A21: 2.5 | B21: 3.72 | C21: =B21*(25.4^2) -> 2399.9952
A22: 2.75 | B22: 4.62 | C22: =B22*(25.4^2) -> 2980.6392
A23: 3 | B23: 5.62 | C23: =B23*(25.4^2) -> 3625.7992
A24: 3.25 | B24: 6.72 | C24: =B24*(25.4^2) -> 4335.4752
A25: 3.5 | B25: 7.92 | C25: =B25*(25.4^2) -> 5109.6672
A26: 3.75 | B26: 9.21 | C26: =B26*(25.4^2) -> 5941.9236
A27: 4 | B27: 10.61 | C27: =B27*(25.4^2) -> 6845.1476

Sheet Material Data
B1: Yield Strength (Mpa) at Temperature (°C)
A2: Material | B2: -30 | C2: 40 | D2: 65 | E2: 100 | F2: 125 | G2: 150 | H2: 175 | I2: 200 | J2: 225 | K2: 250 | L2: 275 | M2: 300 | N2: 325 | O2: 350 | P2: 375 | Q2: 400 | R2: 425 | S2: 450 | T2: 475 | U2: 500 | V2: 525
A3: A105N | B3: 248 | C3: 248 | D3: 233 | E3: 227 | F3: 223 | G3: 219 | H3: 216 | I3: 213 | J3: 209 | K3: 204 | L3: 199 | M3: 194 | N3: 188 | O3: 183 | P3: 177 | Q3: 171 | R3: 166 | S3: 162 | T3: 158 | U3: 154 | V3: 150
A4: A350 Gr LF2 Cl 1 | B4: 248 | C4: 248 | D4: 233 | E4: 227 | F4: 223 | G4: 219 | H4: 216 | I4: 213 | J4: 209 | K4: 204 | L4: 199 | M4: 194 | N4: 188 | O4: 183 | P4: 177 | Q4: 171 | R4: 166 | S4: 162 | T4: 158 | U4: 154 | V4: 150
A5: A182 F51 | B5: 448 | C5: 448 | D5: 418 | E5: 395 | F5: 381 | G5: 370 | H5: 361 | I5: 354 | J5: 349 | K5: 344 | L5: 339 | M5: 334 | N5: 328 | O5: 322 | P5: 0 | Q5: 0 | R5: 0 | S5: 0 | T5: 0 | U5: 0 | V5: 0
A6: A182 F53 UNS S32750 | B6: 552 | C6: 552 | D6: 511 | E6: 481 | F6: 462 | G6: 445 | H6: 432 | I6: 420 | J6: 411 | K6: 404 | L6: 399 | M6: 396 | N6: 394 | O6: 393 | P6: 393 | Q6: 393 | R6: 0 | S6: 0 | T6: 0 | U6: 0 | V6: 0
A7: A182 Gr F316/316L | B7: 207 | C7: 207 | D7: 189 | E7: 176 | F7: 168 | G7: 161 | H7: 154 | I7: 148 | J7: 144 | K7: 139 | L7: 136 | M7: 132 | N7: 129 | O7: 127 | P7: 125 | Q7: 123 | R7: 122 | S7: 121 | T7: 120 | U7: 118 | V7: 117
A8: B381 F2 | B8: 276 | C8: 276 | D8: 238 | E8: 213 | F8: 194 | G8: 176 | H8: 157 | I8: 138 | J8: 121 | K8: 108 | L8: 93.3 | M8: 0 | N8: 0 | O8: 0 | P8: 0 | Q8: 0 | R8: 0 | S8: 0 | T8: 0 | U8: 0 | V8: 0
A14: ASME II Part D (Metric 2011)

Sheet Spec Data
A1: Spec | B1: Material | C1: Rating | D1: Note | E1: Material Group
A2: A1A | B2: A105N | C2: 150# | E2: 1.1
A3: A1B | B3: A105N | C3: 150# | E3: 1.1
A4: A3A | B4: A105N | C4: 300# | E4: 1.1
A5: A3B | B5: A105N | C5: 300# | E5: 1.1
A6: A15A | B6: A105N | C6: 1500# | E6: 1.1
A7: B1A | B7: A105N | C7: 150# | E7: 1.1
A8: B3A | B8: A105N | C8: 300# | E8: 1.1
A9: B6A | B9: A105N | C9: 600# | E9: 1.1
A10: B6B | B10: A105N | C10: 600# | E10: 1.1
A11: B9A | B11: A105N | C11: 900# | E11: 1.1
A12: B15A | B12: A105N | C12: 1500# | E12: 1.1
A13: B25A | B13: A105N | C13: 2500# | E13: 1.1
... A36: S25B | B36: A182 F53 UNS S32750 | C36: 2500# | E36: 2.8
A37: S100B | B37: A182 F53 UNS S32751 | C37: API10000 | D37: API 10,000 SPEC FLANGES | E37: 2.8
A38: T1A | B38: B381 F2 | C38: 150#
A39: X1A | B39: A105N | C39: 150# | E39: 1.1
