Workbook
Name _Toc238552941: 'Data Sheet'!$C$49
Name _Toc238552942: 'Data Sheet'!$C$50
Name Legend: #REF!
Name NPS: 'Appendix 2. Thickness'!$A$4:$A$41
Name SCH: 'Appendix 2. Thickness'!$A$44:$A$162

Sheet XXXXXXX

Sheet Data Sheet
B1: Document Number | D1: PEC-EN-VSS-L-3478
B2: Revision | D2: 0
B3: Applicability | D3: Sharjah, Mumbai, Chennai, Jakarta
B4: Document Type | D4: Spreadsheet
B8: Branch Pipe Connection Reinforcement Calculation as per ASME B31.3
B14: REVISION / APPROVAL HISTORY
B20: 0 | C20: 40283 | D20: Approved | E20: A M Madan | F20: K V Ramesh Govindraj E. Lakshmanan K.S. Venkatesan | G20: A Vaidya
B21: A | C21: 39799 | D21: Draft in development | E21: A M Madan | F21: A Vaidya | G21: B P Gupta
B22: Rev | C22: Date | D22: Description of Change | E22: Originator | F22: Reviewer | G22: Approver
B23: Records of approval are retained in the BMS/Quality Department
B42: CONTENTS
B44: 1 | C44: PURPOSE | G44: 3
B45: 2 | C45: SCOPE | G45: 3
B46: 3 | C46: DEFINITIONS AND ACRONYMS | G46: 3
B47: 3.1 | C47: Definitions | G47: 3
B48: 3.2 | C48: Acronyms | G48: 3
B49: 4 | C49: REFERENCES | G49: 3
B50: 5 | C50: RESPONSIBILITY & AUTHORITY | G50: 3
B51: 6 | C51: DESCRIPTION OF ACTIVITIES | G51: 3
B52: 7 | C52: RECORDS | G52: 3
B53: 8 | C53: APPENDICES | G53: 4
B88: 1.0 PURPOSE
B89: The purpose of the spreadsheet is to check adequacy of the reinforcement in a welded branch pipe connection with or without additional reinforcement pad.
B91: 2.0 SCOPE
B92: This spreadsheet calculates the required and available reinforcements in a welded branch pipe connection with or without additional reinforcement pad. The calculations are done in accordance with ASME B31.3 para 304.3.3.
B94: 3.0 DEFINITIONS AND ACRONYMS
B96: 3.1 Definitions
B97: Welded branch pipe connection is a connection made by welding the branch pipe directly to the run pipe with or without added reinforcement.
B99: 3.2 Acronyms
B100: ASME - American Society of Mechanical Engineers
B101: ASTM - American Society for Testing and Materials
B103: 4.0 REFERENCES
B104: PEC-EN-VSS-L-6490 | D104: Branch Pipe Connection Reinforcement Calculation as per ASME (Validation Record)
B105: ASME B31.3-2008 | D105: PROCESS PIPING
B106: ASME B36.10M-2004 | D106: WELDED AND SEAMLESS WROUGHT STEEL PIPE
B107: ASME B36.19M-2004 | D107: STAINLESS STEEL PIPE
B109: 5.0 RESPONSIBILITY & AUTHORITY
B110: The Material Engineer on the Project shall perform the calculations. These calculations shall be checked by the Lead Material Engineer and shall be reviewed by the Piping Lead Engineer of the Project.
B112: 6.0 DESCRIPTION OF ACTIVITIES
B113: 6.1 | C113: The user shall fill data in the cells highlighted yellow only.
...

Sheet Appendix 1. Calculation
A1: Project: | B1: STELLA | F1: BRANCH PIPE CONNECTION REINFORCEMENT CALCULATION SHEET (ASME B31.3) | M1: Rev: | O1: 0
A2: Client: | B2: ITHACA | M2: Date: | O2: 41615
A3: Job No: | B3: JU-11805D | M3: Prep by: | O3: KK
A4: Doc No: | M4: Chkd by: | O4: SB
B6: The calculations on this sheet are applicable for the following:
B7: DC-28014;S1A
B11: DATA:
B12: Process parameters
C13: Design pressure (internal) | H13: P = | I13: 3.5 | J13: bar g
C14: Design temperature | H14: T = | I14: 115 | J14: oC
H15: = | I15: =IF(I14="","",I14*1.8+32) -> 239 | J15: oF
B17: Material data | I17: Header | M17: Branch
C18: Standard/grade: | H18: A312 Gr316 | L18: A312 Gr316
C19: Stress value | H19: Sh = | I19: =IF(I20="","",I20/145*1000) -> 136.55172 | J19: MPa | L19: Sb = | M19: =IF(M20="","",M20/145*1000) -> 136.55172 | N19: MPa
H20: = | I20: 19.8 | J20: ksi | L20: = | M20: 19.8 | N20: ksi | O20: (Ref. Table A-1, ASME B31.3)
C21: Quality factor | H21: Eh = | I21: 1 | L21: Eb = | M21: 1 | O21: (Ref. Table A-1B, ASME B31.3)
C22: Weld joint strength reduction factor | H22: Wh = | I22: 1 | L22: Wb = | M22: 1 | O22: (Ref. Para 302.3.5(e), ASME B31.3)
C23: Coefficient | H23: Yh = | I23: 0.4 | L23: Yb = | M23: 0.4 | O23: (Ref. Table 304.1.1, ASME B31.3)
T24: PDh/2(ShEhWh + PYh) | U24: PDb/2(SbEbWb + PYb) | V24: T'h(1 - c2h) or (T'h - c3h) | W24: T'b(1 - c2b) or (T'b - c3b) | X24: T'r(1 - c2h) or (T'r - c3h) | Y24: 2.5(Th - c1h) or 2.5(Tb - c1b) + Tr, whichever is less | Z24: [Db - 2(Tb - c1b)]/sinb | AA24: d1 or (Tb - c1b) + (Th - c1h) + d1/2, whichever is greater, but not more than Dh | AB24: Dr or 2d2, whichever is less | AC24: Tr or L4, whichever is less | AD24: 0.7T'b or 6mm, whichever is less | AE24: 0.5T'r | AF24: Treff(Dreff - Db/sinb) [effective Rpad area] | AG24: 2 x ½(tc/0.707)2 [branch weld area] | AH24: Effective branch weld area within reinf zone | AI24: 2 x ½(tr/0.707)2 [Rpad weld area] | AJ24: Effective Rpad weld area within reinf zone | AK24: thd1(2-sinb) | AL24: (2d2 - d1)(Th - th - c1h) | AM24: 2L4(Tb - tb - c1b)/sinb | AN24: X1+ X2+ X3 | AO24: REINFORCEMENT REQUIRED | AP24: REINFORCEMENT AVAILABLE
B25: Allowances
C26: Corrosion allowance | H26: c1h = | I26: 0 | J26: mm | L26: c1b = | M26: 0 | N26: mm
C27: Mill undertolerance on thickness | H27: c2h = | I27: 12.5 | J27: % | L27: c2b = | M27: 12.5 | N27: % | O27: (Refer relevant ASTM standard)
G28: or | H28: c3h = | J28: mm | K28: or | L28: c3b = | N28: mm | O28: (Refer relevant ASTM standard)
G29: =IF(I27>0,IF(I28>0,"Do not enter values for both c2h and c3h!",""),"") | L29: =IF(M27>0,IF(M28>0,"Do not enter values for both c2b and c3b!",""),"")
B31: HEADER PIPE | F31: BRANCH PIPE | K31: REINFORCE-MENT PAD | M31: Reinforcement required | N31: Reinforcement available | O31: Is the reinforce-ment available adequate? | Q31: Remarks
B32: Pipe Size | D32: Wall thickness | F32: Pipe Size | H32: Wall thickness | J32: Angle | K32: Dia | L32: Thk | T32: th= | U32: tb= | V32: Th= | W32: Tb= | X32: Tr= | Y32: L4= | Z32: d1= | AA32: d2= | AB32: Dreff= | AC32: Treff= | AD32: tc= | AE32: tr= | AF32: X1= | AG32: X'2= | AH32: X2= | AI32: X'3= | AJ32: X3= | AK32: A1= | AL32: A2= | AM32: A3= | AN32: A4= | AO32: A1 | AP32: A2+A3 +A4
B33: NPS | C33: Dh | E33: T'h | F33: NPS | G33: Db | I33: T'b | J33: b | K33: Dr | L33: T'r | U33: tb= | V33: Th= | W33: Tb= | X33: Tr= | Y33: L4= | Z33: d1= | AA33: d2= | AB33: Dreff= | AC33: Treff= | AD33: tc= | AE33: tr= | AF33: X1= | AG33: X'2= | AH33: X2= | AI33: X'3= | AJ33: X3= | AK33: A1= | AL33: A2= | AM33: A3= | AN33: A4= | AO33: A1=
B34: inch | C34: mm | D34: Sch/mm | E34: mm | F34: inch | G34: mm | H34: Sch/mm | I34: mm | J34: deg | K34: mm | L34: mm | M34: mm2 | N34: mm2 | T34: mm | U34: mm | V34: mm | W34: mm | X34: mm | Y34: mm | Z34: mm | AA34: mm | AB34: mm | AC34: mm | AD34: mm | AE34: mm | AF34: mm2 | AG34: mm2 | AH34: mm2 | AI34: mm2 | AJ34: mm2 | AK34: mm2 | AL34: mm2 | AM34: mm2 | AN34: mm2 | AO34: mm2 | AP34: mm2
B35: 6 | C35: =IF(B35>0,VLOOKUP(B35,'Appendix 2. Thickness'!$A$3:$B$41,2,FALSE),"") -> 168.3 | D35: Sch10 | E35: =IF(D35>0,IF(ISNUMBER(D35),D35,VLOOKUP(B35,'Appendix 2. Thickness'!$A$4:$T$41,(MATCH(D35,'Appendix 2. Thickness'!$C$3:$T$3,0)+2),FALSE)),"") -> 3.4 | F35: 4 | G35: =IF(F35>0,VLOOKUP(F35,'Appendix 2. Thickness'!$A$3:$B$41,2,FALSE),"") -> 114.3 | H35: Sch10 | I35: =IF(H35>0,IF(ISNUMBER(H35),H35,VLOOKUP(F35,'Appendix 2. Thickness'!$A$4:$T$41,(MATCH(H35,'Appendix 2. Thickness'!$C$3:$T$3,0)+2),FALSE)),"") -> 3.05 | J35: 45 | K35: 228 | L35: 3.4 | M35: =IF(B35>0,AK35,"") -> 42.927407 | N35: =IF(B35>0,(AL35+AM35+AN35),"") -> 690.60011 | O35: =IF(B35>0,(IF(M35<=N35,"YES","NO")),"") -> YES | T35: =($I$13/10)*C35/(2*($I$19*$I$21*$I$22+($I$13/10)*$I$23)) -> 0.21546659 | U35: =($I$13/10)*G35/(2*($M$19*$M$21*$M$22+($I$13/10)*$M$23)) -> 0.14633293 | V35: =E35*(1-$I$27/100)-$I$28 -> 2.975 | W35: =I35*(1-$M$27/100)-$M$28 -> 2.66875 | X35: =IF(L35>0,(L35*(1-$I$27/100)-$I$28),0) -> 2.975 | Y35: =MIN(2.5*(V35-$I$26),2.5*(W35-$M$26)+X35) -> 7.4375 | Z35: =(G35-2*(W35-$M$26))/SIN(J35*PI()/180) -> 154.09625 | AA35: =MIN(MAX(Z35,(W35-$M$26)+(V35-$I$26)+Z35/2),C35) -> 154.09625 | AB35: =MIN(K35,2*AA35) -> 228 | AC35: =MIN(X35,Y35) -> 2.975 | AD35: =MIN(0.7*I35,6) -> 2.135 | AE35: =0.5*L35 -> 1.7 | AF35: =AC35*(AB35-G35/SIN(J35*PI()/180)) -> 197.40728 | AG35: =2*AD35^2 -> 9.11645 | AH35: =IF((X35+AD35*SQRT(2))>Y35,IF(X35<Y35,(AG35-((X35+AD35*SQRT(2))-Y35)^2),0),AG35) -> 9.11645 | AI35: =2*AE35^2 -> 5.78 | AJ35: =IF((K35/2+AE35*SQRT(2))>AA35,IF(K35/2<AA35,(AI35-((K35/2+AE35*SQRT(2))-AA35)^2),0),AI35) -> 5.78 | AK35: =T35*Z35*(2-SIN(J35*PI()/180)) -> 42.927407 | AL35: =(2*AA35-Z35)*(V35-T35-$I$26) -> 425.23374 | AM35: =MIN(2*Y35*(W35-U35-$M$26)/SIN(J35*PI()/180),2*Y35*(W35-U35-$M$26)/SIN(J35*PI()/180)*($M$19/$I$19)) -> 53.062642 | AN35: =AF35+AH35+AJ35 -> 212.30373 | AO35: =AK35 -> 42.927407 | AP35: =AL35+AM35+AN35 -> 690.60011
C36: =IF(B36>0,VLOOKUP(B36,'Appendix 2. Thickness'!$A$3:$B$41,2,FALSE),"") | E36: =IF(D36>0,IF(ISNUMBER(D36),D36,VLOOKUP(B36,'Appendix 2. Thickness'!$A$4:$T$41,(MATCH(D36,'Appendix 2. Thickness'!$C$3:$T$3,0)+2),FALSE)),"") | G36: =IF(F36>0,VLOOKUP(F36,'Appendix 2. Thickness'!$A$3:$B$41,2,FALSE),"") | I36: =IF(H36>0,IF(ISNUMBER(H36),H36,VLOOKUP(F36,'Appendix 2. Thickness'!$A$4:$T$41,(MATCH(H36,'Appendix 2. Thickness'!$C$3:$T$3,0)+2),FALSE)),"") | M36: =IF(B36>0,AK36,"") | N36: =IF(B36>0,(AL36+AM36+AN36),"") | O36: =IF(B36>0,(IF(M36<=N36,"YES","NO")),"") | T36: =($I$13/10)*C36/(2*($I$19*$I$21*$I$22+($I$13/10)*$I$23)) -> #VALUE! | U36: =($I$13/10)*G36/(2*($M$19*$M$21*$M$22+($I$13/10)*$M$23)) -> #VALUE! | V36: =E36*(1-$I$27/100)-$I$28 -> #VALUE! | W36: =I36*(1-$M$27/100)-$M$28 -> #VALUE! | X36: =IF(L36>0,(L36*(1-$I$27/100)-$I$28),0) -> 0 | Y36: =MIN(2.5*(V36-$I$26),2.5*(W36-$M$26)+X36) -> #VALUE! | Z36: =(G36-2*(W36-$M$26))/SIN(J36*PI()/180) -> #VALUE! | AA36: =MIN(MAX(Z36,(W36-$M$26)+(V36-$I$26)+Z36/2),C36) -> #VALUE! | AB36: =MIN(K36,2*AA36) -> #VALUE! | AC36: =MIN(X36,Y36) -> #VALUE! | AD36: =MIN(0.7*I36,6) -> #VALUE! | AE36: =0.5*L36 -> 0 | AF36: =AC36*(AB36-G36/SIN(J36*PI()/180)) -> #VALUE! | AG36: =2*AD36^2 -> #VALUE! | AH36: =IF((X36+AD36*SQRT(2))>Y36,IF(X36<Y36,(AG36-((X36+AD36*SQRT(2))-Y36)^2),0),AG36) -> #VALUE! | AI36: =2*AE36^2 -> 0 | AJ36: =IF((K36/2+AE36*SQRT(2))>AA36,IF(K36/2<AA36,(AI36-((K36/2+AE36*SQRT(2))-AA36)^2),0),AI36) -> #VALUE! | AK36: =T36*Z36*(2-SIN(J36*PI()/180)) -> #VALUE! | AL36: =(2*AA36-Z36)*(V36-T36-$I$26) -> #VALUE! | AM36: =MIN(2*Y36*(W36-U36-$M$26)/SIN(J36*PI()/180),2*Y36*(W36-U36-$M$26)/SIN(J36*PI()/180)*($M$19/$I$19)) -> #VALUE! | AN36: =AF36+AH36+AJ36 -> #VALUE! | AO36: =AK36 -> #VALUE! | AP36: =AL36+AM36+AN36 -> #VALUE!
C37: =IF(B37>0,VLOOKUP(B37,'Appendix 2. Thickness'!$A$3:$B$41,2,FALSE),"") | E37: =IF(D37>0,IF(ISNUMBER(D37),D37,VLOOKUP(B37,'Appendix 2. Thickness'!$A$4:$T$41,(MATCH(D37,'Appendix 2. Thickness'!$C$3:$T$3,0)+2),FALSE)),"") | G37: =IF(F37>0,VLOOKUP(F37,'Appendix 2. Thickness'!$A$3:$B$41,2,FALSE),"") | I37: =IF(H37>0,IF(ISNUMBER(H37),H37,VLOOKUP(F37,'Appendix 2. Thickness'!$A$4:$T$41,(MATCH(H37,'Appendix 2. Thickness'!$C$3:$T$3,0)+2),FALSE)),"") | M37: =IF(B37>0,AK37,"") | N37: =IF(B37>0,(AL37+AM37+AN37),"") | O37: =IF(B37>0,(IF(M37<=N37,"YES","NO")),"") | T37: =($I$13/10)*C37/(2*($I$19*$I$21*$I$22+($I$13/10)*$I$23)) -> #VALUE! | U37: =($I$13/10)*G37/(2*($M$19*$M$21*$M$22+($I$13/10)*$M$23)) -> #VALUE! | V37: =E37*(1-$I$27/100)-$I$28 -> #VALUE! | W37: =I37*(1-$M$27/100)-$M$28 -> #VALUE! | X37: =IF(L37>0,(L37*(1-$I$27/100)-$I$28),0) -> 0 | Y37: =MIN(2.5*(V37-$I$26),2.5*(W37-$M$26)+X37) -> #VALUE! | Z37: =(G37-2*(W37-$M$26))/SIN(J37*PI()/180) -> #VALUE! | AA37: =MIN(MAX(Z37,(W37-$M$26)+(V37-$I$26)+Z37/2),C37) -> #VALUE! | AB37: =MIN(K37,2*AA37) -> #VALUE! | AC37: =MIN(X37,Y37) -> #VALUE! | AD37: =MIN(0.7*I37,6) -> #VALUE! | AE37: =0.5*L37 -> 0 | AF37: =AC37*(AB37-G37/SIN(J37*PI()/180)) -> #VALUE! | AG37: =2*AD37^2 -> #VALUE! | AH37: =IF((X37+AD37*SQRT(2))>Y37,IF(X37<Y37,(AG37-((X37+AD37*SQRT(2))-Y37)^2),0),AG37) -> #VALUE! | AI37: =2*AE37^2 -> 0 | AJ37: =IF((K37/2+AE37*SQRT(2))>AA37,IF(K37/2<AA37,(AI37-((K37/2+AE37*SQRT(2))-AA37)^2),0),AI37) -> #VALUE! | AK37: =T37*Z37*(2-SIN(J37*PI()/180)) -> #VALUE! | AL37: =(2*AA37-Z37)*(V37-T37-$I$26) -> #VALUE! | AM37: =MIN(2*Y37*(W37-U37-$M$26)/SIN(J37*PI()/180),2*Y37*(W37-U37-$M$26)/SIN(J37*PI()/180)*($M$19/$I$19)) -> #VALUE! | AN37: =AF37+AH37+AJ37 -> #VALUE! | AO37: =AK37 -> #VALUE! | AP37: =AL37+AM37+AN37 -> #VALUE!
C38: =IF(B38>0,VLOOKUP(B38,'Appendix 2. Thickness'!$A$3:$B$41,2,FALSE),"") | E38: =IF(D38>0,IF(ISNUMBER(D38),D38,VLOOKUP(B38,'Appendix 2. Thickness'!$A$4:$T$41,(MATCH(D38,'Appendix 2. Thickness'!$C$3:$T$3,0)+2),FALSE)),"") | G38: =IF(F38>0,VLOOKUP(F38,'Appendix 2. Thickness'!$A$3:$B$41,2,FALSE),"") | I38: =IF(H38>0,IF(ISNUMBER(H38),H38,VLOOKUP(F38,'Appendix 2. Thickness'!$A$4:$T$41,(MATCH(H38,'Appendix 2. Thickness'!$C$3:$T$3,0)+2),FALSE)),"") | M38: =IF(B38>0,AK38,"") | N38: =IF(B38>0,(AL38+AM38+AN38),"") | O38: =IF(B38>0,(IF(M38<=N38,"YES","NO")),"") | T38: =($I$13/10)*C38/(2*($I$19*$I$21*$I$22+($I$13/10)*$I$23)) -> #VALUE! | U38: =($I$13/10)*G38/(2*($M$19*$M$21*$M$22+($I$13/10)*$M$23)) -> #VALUE! | V38: =E38*(1-$I$27/100)-$I$28 -> #VALUE! | W38: =I38*(1-$M$27/100)-$M$28 -> #VALUE! | X38: =IF(L38>0,(L38*(1-$I$27/100)-$I$28),0) -> 0 | Y38: =MIN(2.5*(V38-$I$26),2.5*(W38-$M$26)+X38) -> #VALUE! | Z38: =(G38-2*(W38-$M$26))/SIN(J38*PI()/180) -> #VALUE! | AA38: =MIN(MAX(Z38,(W38-$M$26)+(V38-$I$26)+Z38/2),C38) -> #VALUE! | AB38: =MIN(K38,2*AA38) -> #VALUE! | AC38: =MIN(X38,Y38) -> #VALUE! | AD38: =MIN(0.7*I38,6) -> #VALUE! | AE38: =0.5*L38 -> 0 | AF38: =AC38*(AB38-G38/SIN(J38*PI()/180)) -> #VALUE! | AG38: =2*AD38^2 -> #VALUE! | AH38: =IF((X38+AD38*SQRT(2))>Y38,IF(X38<Y38,(AG38-((X38+AD38*SQRT(2))-Y38)^2),0),AG38) -> #VALUE! | AI38: =2*AE38^2 -> 0 | AJ38: =IF((K38/2+AE38*SQRT(2))>AA38,IF(K38/2<AA38,(AI38-((K38/2+AE38*SQRT(2))-AA38)^2),0),AI38) -> #VALUE! | AK38: =T38*Z38*(2-SIN(J38*PI()/180)) -> #VALUE! | AL38: =(2*AA38-Z38)*(V38-T38-$I$26) -> #VALUE! | AM38: =MIN(2*Y38*(W38-U38-$M$26)/SIN(J38*PI()/180),2*Y38*(W38-U38-$M$26)/SIN(J38*PI()/180)*($M$19/$I$19)) -> #VALUE! | AN38: =AF38+AH38+AJ38 -> #VALUE! | AO38: =AK38 -> #VALUE! | AP38: =AL38+AM38+AN38 -> #VALUE!
C39: =IF(B39>0,VLOOKUP(B39,'Appendix 2. Thickness'!$A$3:$B$41,2,FALSE),"") | E39: =IF(D39>0,IF(ISNUMBER(D39),D39,VLOOKUP(B39,'Appendix 2. Thickness'!$A$4:$T$41,(MATCH(D39,'Appendix 2. Thickness'!$C$3:$T$3,0)+2),FALSE)),"") | G39: =IF(F39>0,VLOOKUP(F39,'Appendix 2. Thickness'!$A$3:$B$41,2,FALSE),"") | I39: =IF(H39>0,IF(ISNUMBER(H39),H39,VLOOKUP(F39,'Appendix 2. Thickness'!$A$4:$T$41,(MATCH(H39,'Appendix 2. Thickness'!$C$3:$T$3,0)+2),FALSE)),"") | M39: =IF(B39>0,AK39,"") | N39: =IF(B39>0,(AL39+AM39+AN39),"") | O39: =IF(B39>0,(IF(M39<=N39,"YES","NO")),"") | T39: =($I$13/10)*C39/(2*($I$19*$I$21*$I$22+($I$13/10)*$I$23)) -> #VALUE! | U39: =($I$13/10)*G39/(2*($M$19*$M$21*$M$22+($I$13/10)*$M$23)) -> #VALUE! | V39: =E39*(1-$I$27/100)-$I$28 -> #VALUE! | W39: =I39*(1-$M$27/100)-$M$28 -> #VALUE! | X39: =IF(L39>0,(L39*(1-$I$27/100)-$I$28),0) -> 0 | Y39: =MIN(2.5*(V39-$I$26),2.5*(W39-$M$26)+X39) -> #VALUE! | Z39: =(G39-2*(W39-$M$26))/SIN(J39*PI()/180) -> #VALUE! | AA39: =MIN(MAX(Z39,(W39-$M$26)+(V39-$I$26)+Z39/2),C39) -> #VALUE! | AB39: =MIN(K39,2*AA39) -> #VALUE! | AC39: =MIN(X39,Y39) -> #VALUE! | AD39: =MIN(0.7*I39,6) -> #VALUE! | AE39: =0.5*L39 -> 0 | AF39: =AC39*(AB39-G39/SIN(J39*PI()/180)) -> #VALUE! | AG39: =2*AD39^2 -> #VALUE! | AH39: =IF((X39+AD39*SQRT(2))>Y39,IF(X39<Y39,(AG39-((X39+AD39*SQRT(2))-Y39)^2),0),AG39) -> #VALUE! | AI39: =2*AE39^2 -> 0 | AJ39: =IF((K39/2+AE39*SQRT(2))>AA39,IF(K39/2<AA39,(AI39-((K39/2+AE39*SQRT(2))-AA39)^2),0),AI39) -> #VALUE! | AK39: =T39*Z39*(2-SIN(J39*PI()/180)) -> #VALUE! | AL39: =(2*AA39-Z39)*(V39-T39-$I$26) -> #VALUE! | AM39: =MIN(2*Y39*(W39-U39-$M$26)/SIN(J39*PI()/180),2*Y39*(W39-U39-$M$26)/SIN(J39*PI()/180)*($M$19/$I$19)) -> #VALUE! | AN39: =AF39+AH39+AJ39 -> #VALUE! | AO39: =AK39 -> #VALUE! | AP39: =AL39+AM39+AN39 -> #VALUE!
C40: =IF(B40>0,VLOOKUP(B40,'Appendix 2. Thickness'!$A$3:$B$41,2,FALSE),"") | E40: =IF(D40>0,IF(ISNUMBER(D40),D40,VLOOKUP(B40,'Appendix 2. Thickness'!$A$4:$T$41,(MATCH(D40,'Appendix 2. Thickness'!$C$3:$T$3,0)+2),FALSE)),"") | G40: =IF(F40>0,VLOOKUP(F40,'Appendix 2. Thickness'!$A$3:$B$41,2,FALSE),"") | I40: =IF(H40>0,IF(ISNUMBER(H40),H40,VLOOKUP(F40,'Appendix 2. Thickness'!$A$4:$T$41,(MATCH(H40,'Appendix 2. Thickness'!$C$3:$T$3,0)+2),FALSE)),"") | M40: =IF(B40>0,AK40,"") | N40: =IF(B40>0,(AL40+AM40+AN40),"") | O40: =IF(B40>0,(IF(M40<=N40,"YES","NO")),"") | T40: =($I$13/10)*C40/(2*($I$19*$I$21*$I$22+($I$13/10)*$I$23)) -> #VALUE! | U40: =($I$13/10)*G40/(2*($M$19*$M$21*$M$22+($I$13/10)*$M$23)) -> #VALUE! | V40: =E40*(1-$I$27/100)-$I$28 -> #VALUE! | W40: =I40*(1-$M$27/100)-$M$28 -> #VALUE! | X40: =IF(L40>0,(L40*(1-$I$27/100)-$I$28),0) -> 0 | Y40: =MIN(2.5*(V40-$I$26),2.5*(W40-$M$26)+X40) -> #VALUE! | Z40: =(G40-2*(W40-$M$26))/SIN(J40*PI()/180) -> #VALUE! | AA40: =MIN(MAX(Z40,(W40-$M$26)+(V40-$I$26)+Z40/2),C40) -> #VALUE! | AB40: =MIN(K40,2*AA40) -> #VALUE! | AC40: =MIN(X40,Y40) -> #VALUE! | AD40: =MIN(0.7*I40,6) -> #VALUE! | AE40: =0.5*L40 -> 0 | AF40: =AC40*(AB40-G40/SIN(J40*PI()/180)) -> #VALUE! | AG40: =2*AD40^2 -> #VALUE! | AH40: =IF((X40+AD40*SQRT(2))>Y40,IF(X40<Y40,(AG40-((X40+AD40*SQRT(2))-Y40)^2),0),AG40) -> #VALUE! | AI40: =2*AE40^2 -> 0 | AJ40: =IF((K40/2+AE40*SQRT(2))>AA40,IF(K40/2<AA40,(AI40-((K40/2+AE40*SQRT(2))-AA40)^2),0),AI40) -> #VALUE! | AK40: =T40*Z40*(2-SIN(J40*PI()/180)) -> #VALUE! | AL40: =(2*AA40-Z40)*(V40-T40-$I$26) -> #VALUE! | AM40: =MIN(2*Y40*(W40-U40-$M$26)/SIN(J40*PI()/180),2*Y40*(W40-U40-$M$26)/SIN(J40*PI()/180)*($M$19/$I$19)) -> #VALUE! | AN40: =AF40+AH40+AJ40 -> #VALUE! | AO40: =AK40 -> #VALUE! | AP40: =AL40+AM40+AN40 -> #VALUE!
C41: =IF(B41>0,VLOOKUP(B41,'Appendix 2. Thickness'!$A$3:$B$41,2,FALSE),"") | E41: =IF(D41>0,IF(ISNUMBER(D41),D41,VLOOKUP(B41,'Appendix 2. Thickness'!$A$4:$T$41,(MATCH(D41,'Appendix 2. Thickness'!$C$3:$T$3,0)+2),FALSE)),"") | G41: =IF(F41>0,VLOOKUP(F41,'Appendix 2. Thickness'!$A$3:$B$41,2,FALSE),"") | I41: =IF(H41>0,IF(ISNUMBER(H41),H41,VLOOKUP(F41,'Appendix 2. Thickness'!$A$4:$T$41,(MATCH(H41,'Appendix 2. Thickness'!$C$3:$T$3,0)+2),FALSE)),"") | M41: =IF(B41>0,AK41,"") | N41: =IF(B41>0,(AL41+AM41+AN41),"") | O41: =IF(B41>0,(IF(M41<=N41,"YES","NO")),"") | T41: =($I$13/10)*C41/(2*($I$19*$I$21*$I$22+($I$13/10)*$I$23)) -> #VALUE! | U41: =($I$13/10)*G41/(2*($M$19*$M$21*$M$22+($I$13/10)*$M$23)) -> #VALUE! | V41: =E41*(1-$I$27/100)-$I$28 -> #VALUE! | W41: =I41*(1-$M$27/100)-$M$28 -> #VALUE! | X41: =IF(L41>0,(L41*(1-$I$27/100)-$I$28),0) -> 0 | Y41: =MIN(2.5*(V41-$I$26),2.5*(W41-$M$26)+X41) -> #VALUE! | Z41: =(G41-2*(W41-$M$26))/SIN(J41*PI()/180) -> #VALUE! | AA41: =MIN(MAX(Z41,(W41-$M$26)+(V41-$I$26)+Z41/2),C41) -> #VALUE! | AB41: =MIN(K41,2*AA41) -> #VALUE! | AC41: =MIN(X41,Y41) -> #VALUE! | AD41: =MIN(0.7*I41,6) -> #VALUE! | AE41: =0.5*L41 -> 0 | AF41: =AC41*(AB41-G41/SIN(J41*PI()/180)) -> #VALUE! | AG41: =2*AD41^2 -> #VALUE! | AH41: =IF((X41+AD41*SQRT(2))>Y41,IF(X41<Y41,(AG41-((X41+AD41*SQRT(2))-Y41)^2),0),AG41) -> #VALUE! | AI41: =2*AE41^2 -> 0 | AJ41: =IF((K41/2+AE41*SQRT(2))>AA41,IF(K41/2<AA41,(AI41-((K41/2+AE41*SQRT(2))-AA41)^2),0),AI41) -> #VALUE! | AK41: =T41*Z41*(2-SIN(J41*PI()/180)) -> #VALUE! | AL41: =(2*AA41-Z41)*(V41-T41-$I$26) -> #VALUE! | AM41: =MIN(2*Y41*(W41-U41-$M$26)/SIN(J41*PI()/180),2*Y41*(W41-U41-$M$26)/SIN(J41*PI()/180)*($M$19/$I$19)) -> #VALUE! | AN41: =AF41+AH41+AJ41 -> #VALUE! | AO41: =AK41 -> #VALUE! | AP41: =AL41+AM41+AN41 -> #VALUE!
C42: =IF(B42>0,VLOOKUP(B42,'Appendix 2. Thickness'!$A$3:$B$41,2,FALSE),"") | E42: =IF(D42>0,IF(ISNUMBER(D42),D42,VLOOKUP(B42,'Appendix 2. Thickness'!$A$4:$T$41,(MATCH(D42,'Appendix 2. Thickness'!$C$3:$T$3,0)+2),FALSE)),"") | G42: =IF(F42>0,VLOOKUP(F42,'Appendix 2. Thickness'!$A$3:$B$41,2,FALSE),"") | I42: =IF(H42>0,IF(ISNUMBER(H42),H42,VLOOKUP(F42,'Appendix 2. Thickness'!$A$4:$T$41,(MATCH(H42,'Appendix 2. Thickness'!$C$3:$T$3,0)+2),FALSE)),"") | M42: =IF(B42>0,AK42,"") | N42: =IF(B42>0,(AL42+AM42+AN42),"") | O42: =IF(B42>0,(IF(M42<=N42,"YES","NO")),"") | T42: =($I$13/10)*C42/(2*($I$19*$I$21*$I$22+($I$13/10)*$I$23)) -> #VALUE! | U42: =($I$13/10)*G42/(2*($M$19*$M$21*$M$22+($I$13/10)*$M$23)) -> #VALUE! | V42: =E42*(1-$I$27/100)-$I$28 -> #VALUE! | W42: =I42*(1-$M$27/100)-$M$28 -> #VALUE! | X42: =IF(L42>0,(L42*(1-$I$27/100)-$I$28),0) -> 0 | Y42: =MIN(2.5*(V42-$I$26),2.5*(W42-$M$26)+X42) -> #VALUE! | Z42: =(G42-2*(W42-$M$26))/SIN(J42*PI()/180) -> #VALUE! | AA42: =MIN(MAX(Z42,(W42-$M$26)+(V42-$I$26)+Z42/2),C42) -> #VALUE! | AB42: =MIN(K42,2*AA42) -> #VALUE! | AC42: =MIN(X42,Y42) -> #VALUE! | AD42: =MIN(0.7*I42,6) -> #VALUE! | AE42: =0.5*L42 -> 0 | AF42: =AC42*(AB42-G42/SIN(J42*PI()/180)) -> #VALUE! | AG42: =2*AD42^2 -> #VALUE! | AH42: =IF((X42+AD42*SQRT(2))>Y42,IF(X42<Y42,(AG42-((X42+AD42*SQRT(2))-Y42)^2),0),AG42) -> #VALUE! | AI42: =2*AE42^2 -> 0 | AJ42: =IF((K42/2+AE42*SQRT(2))>AA42,IF(K42/2<AA42,(AI42-((K42/2+AE42*SQRT(2))-AA42)^2),0),AI42) -> #VALUE! | AK42: =T42*Z42*(2-SIN(J42*PI()/180)) -> #VALUE! | AL42: =(2*AA42-Z42)*(V42-T42-$I$26) -> #VALUE! | AM42: =MIN(2*Y42*(W42-U42-$M$26)/SIN(J42*PI()/180),2*Y42*(W42-U42-$M$26)/SIN(J42*PI()/180)*($M$19/$I$19)) -> #VALUE! | AN42: =AF42+AH42+AJ42 -> #VALUE! | AO42: =AK42 -> #VALUE! | AP42: =AL42+AM42+AN42 -> #VALUE!
C43: =IF(B43>0,VLOOKUP(B43,'Appendix 2. Thickness'!$A$3:$B$41,2,FALSE),"") | E43: =IF(D43>0,IF(ISNUMBER(D43),D43,VLOOKUP(B43,'Appendix 2. Thickness'!$A$4:$T$41,(MATCH(D43,'Appendix 2. Thickness'!$C$3:$T$3,0)+2),FALSE)),"") | G43: =IF(F43>0,VLOOKUP(F43,'Appendix 2. Thickness'!$A$3:$B$41,2,FALSE),"") | I43: =IF(H43>0,IF(ISNUMBER(H43),H43,VLOOKUP(F43,'Appendix 2. Thickness'!$A$4:$T$41,(MATCH(H43,'Appendix 2. Thickness'!$C$3:$T$3,0)+2),FALSE)),"") | M43: =IF(B43>0,AK43,"") | N43: =IF(B43>0,(AL43+AM43+AN43),"") | O43: =IF(B43>0,(IF(M43<=N43,"YES","NO")),"") | T43: =($I$13/10)*C43/(2*($I$19*$I$21*$I$22+($I$13/10)*$I$23)) -> #VALUE! | U43: =($I$13/10)*G43/(2*($M$19*$M$21*$M$22+($I$13/10)*$M$23)) -> #VALUE! | V43: =E43*(1-$I$27/100)-$I$28 -> #VALUE! | W43: =I43*(1-$M$27/100)-$M$28 -> #VALUE! | X43: =IF(L43>0,(L43*(1-$I$27/100)-$I$28),0) -> 0 | Y43: =MIN(2.5*(V43-$I$26),2.5*(W43-$M$26)+X43) -> #VALUE! | Z43: =(G43-2*(W43-$M$26))/SIN(J43*PI()/180) -> #VALUE! | AA43: =MIN(MAX(Z43,(W43-$M$26)+(V43-$I$26)+Z43/2),C43) -> #VALUE! | AB43: =MIN(K43,2*AA43) -> #VALUE! | AC43: =MIN(X43,Y43) -> #VALUE! | AD43: =MIN(0.7*I43,6) -> #VALUE! | AE43: =0.5*L43 -> 0 | AF43: =AC43*(AB43-G43/SIN(J43*PI()/180)) -> #VALUE! | AG43: =2*AD43^2 -> #VALUE! | AH43: =IF((X43+AD43*SQRT(2))>Y43,IF(X43<Y43,(AG43-((X43+AD43*SQRT(2))-Y43)^2),0),AG43) -> #VALUE! | AI43: =2*AE43^2 -> 0 | AJ43: =IF((K43/2+AE43*SQRT(2))>AA43,IF(K43/2<AA43,(AI43-((K43/2+AE43*SQRT(2))-AA43)^2),0),AI43) -> #VALUE! | AK43: =T43*Z43*(2-SIN(J43*PI()/180)) -> #VALUE! | AL43: =(2*AA43-Z43)*(V43-T43-$I$26) -> #VALUE! | AM43: =MIN(2*Y43*(W43-U43-$M$26)/SIN(J43*PI()/180),2*Y43*(W43-U43-$M$26)/SIN(J43*PI()/180)*($M$19/$I$19)) -> #VALUE! | AN43: =AF43+AH43+AJ43 -> #VALUE! | AO43: =AK43 -> #VALUE! | AP43: =AL43+AM43+AN43 -> #VALUE!
C44: =IF(B44>0,VLOOKUP(B44,'Appendix 2. Thickness'!$A$3:$B$41,2,FALSE),"") | E44: =IF(D44>0,IF(ISNUMBER(D44),D44,VLOOKUP(B44,'Appendix 2. Thickness'!$A$4:$T$41,(MATCH(D44,'Appendix 2. Thickness'!$C$3:$T$3,0)+2),FALSE)),"") | G44: =IF(F44>0,VLOOKUP(F44,'Appendix 2. Thickness'!$A$3:$B$41,2,FALSE),"") | I44: =IF(H44>0,IF(ISNUMBER(H44),H44,VLOOKUP(F44,'Appendix 2. Thickness'!$A$4:$T$41,(MATCH(H44,'Appendix 2. Thickness'!$C$3:$T$3,0)+2),FALSE)),"") | M44: =IF(B44>0,AK44,"") | N44: =IF(B44>0,(AL44+AM44+AN44),"") | O44: =IF(B44>0,(IF(M44<=N44,"YES","NO")),"") | T44: =($I$13/10)*C44/(2*($I$19*$I$21*$I$22+($I$13/10)*$I$23)) -> #VALUE! | U44: =($I$13/10)*G44/(2*($M$19*$M$21*$M$22+($I$13/10)*$M$23)) -> #VALUE! | V44: =E44*(1-$I$27/100)-$I$28 -> #VALUE! | W44: =I44*(1-$M$27/100)-$M$28 -> #VALUE! | X44: =IF(L44>0,(L44*(1-$I$27/100)-$I$28),0) -> 0 | Y44: =MIN(2.5*(V44-$I$26),2.5*(W44-$M$26)+X44) -> #VALUE! | Z44: =(G44-2*(W44-$M$26))/SIN(J44*PI()/180) -> #VALUE! | AA44: =MIN(MAX(Z44,(W44-$M$26)+(V44-$I$26)+Z44/2),C44) -> #VALUE! | AB44: =MIN(K44,2*AA44) -> #VALUE! | AC44: =MIN(X44,Y44) -> #VALUE! | AD44: =MIN(0.7*I44,6) -> #VALUE! | AE44: =0.5*L44 -> 0 | AF44: =AC44*(AB44-G44/SIN(J44*PI()/180)) -> #VALUE! | AG44: =2*AD44^2 -> #VALUE! | AH44: =IF((X44+AD44*SQRT(2))>Y44,IF(X44<Y44,(AG44-((X44+AD44*SQRT(2))-Y44)^2),0),AG44) -> #VALUE! | AI44: =2*AE44^2 -> 0 | AJ44: =IF((K44/2+AE44*SQRT(2))>AA44,IF(K44/2<AA44,(AI44-((K44/2+AE44*SQRT(2))-AA44)^2),0),AI44) -> #VALUE! | AK44: =T44*Z44*(2-SIN(J44*PI()/180)) -> #VALUE! | AL44: =(2*AA44-Z44)*(V44-T44-$I$26) -> #VALUE! | AM44: =MIN(2*Y44*(W44-U44-$M$26)/SIN(J44*PI()/180),2*Y44*(W44-U44-$M$26)/SIN(J44*PI()/180)*($M$19/$I$19)) -> #VALUE! | AN44: =AF44+AH44+AJ44 -> #VALUE! | AO44: =AK44 -> #VALUE! | AP44: =AL44+AM44+AN44 -> #VALUE!
C45: =IF(B45>0,VLOOKUP(B45,'Appendix 2. Thickness'!$A$3:$B$41,2,FALSE),"") | E45: =IF(D45>0,IF(ISNUMBER(D45),D45,VLOOKUP(B45,'Appendix 2. Thickness'!$A$4:$T$41,(MATCH(D45,'Appendix 2. Thickness'!$C$3:$T$3,0)+2),FALSE)),"") | G45: =IF(F45>0,VLOOKUP(F45,'Appendix 2. Thickness'!$A$3:$B$41,2,FALSE),"") | I45: =IF(H45>0,IF(ISNUMBER(H45),H45,VLOOKUP(F45,'Appendix 2. Thickness'!$A$4:$T$41,(MATCH(H45,'Appendix 2. Thickness'!$C$3:$T$3,0)+2),FALSE)),"") | M45: =IF(B45>0,AK45,"") | N45: =IF(B45>0,(AL45+AM45+AN45),"") | O45: =IF(B45>0,(IF(M45<=N45,"YES","NO")),"") | T45: =($I$13/10)*C45/(2*($I$19*$I$21*$I$22+($I$13/10)*$I$23)) -> #VALUE! | U45: =($I$13/10)*G45/(2*($M$19*$M$21*$M$22+($I$13/10)*$M$23)) -> #VALUE! | V45: =E45*(1-$I$27/100)-$I$28 -> #VALUE! | W45: =I45*(1-$M$27/100)-$M$28 -> #VALUE! | X45: =IF(L45>0,(L45*(1-$I$27/100)-$I$28),0) -> 0 | Y45: =MIN(2.5*(V45-$I$26),2.5*(W45-$M$26)+X45) -> #VALUE! | Z45: =(G45-2*(W45-$M$26))/SIN(J45*PI()/180) -> #VALUE! | AA45: =MIN(MAX(Z45,(W45-$M$26)+(V45-$I$26)+Z45/2),C45) -> #VALUE! | AB45: =MIN(K45,2*AA45) -> #VALUE! | AC45: =MIN(X45,Y45) -> #VALUE! | AD45: =MIN(0.7*I45,6) -> #VALUE! | AE45: =0.5*L45 -> 0 | AF45: =AC45*(AB45-G45/SIN(J45*PI()/180)) -> #VALUE! | AG45: =2*AD45^2 -> #VALUE! | AH45: =IF((X45+AD45*SQRT(2))>Y45,IF(X45<Y45,(AG45-((X45+AD45*SQRT(2))-Y45)^2),0),AG45) -> #VALUE! | AI45: =2*AE45^2 -> 0 | AJ45: =IF((K45/2+AE45*SQRT(2))>AA45,IF(K45/2<AA45,(AI45-((K45/2+AE45*SQRT(2))-AA45)^2),0),AI45) -> #VALUE! | AK45: =T45*Z45*(2-SIN(J45*PI()/180)) -> #VALUE! | AL45: =(2*AA45-Z45)*(V45-T45-$I$26) -> #VALUE! | AM45: =MIN(2*Y45*(W45-U45-$M$26)/SIN(J45*PI()/180),2*Y45*(W45-U45-$M$26)/SIN(J45*PI()/180)*($M$19/$I$19)) -> #VALUE! | AN45: =AF45+AH45+AJ45 -> #VALUE! | AO45: =AK45 -> #VALUE! | AP45: =AL45+AM45+AN45 -> #VALUE!
C46: =IF(B46>0,VLOOKUP(B46,'Appendix 2. Thickness'!$A$3:$B$41,2,FALSE),"") | E46: =IF(D46>0,IF(ISNUMBER(D46),D46,VLOOKUP(B46,'Appendix 2. Thickness'!$A$4:$T$41,(MATCH(D46,'Appendix 2. Thickness'!$C$3:$T$3,0)+2),FALSE)),"") | G46: =IF(F46>0,VLOOKUP(F46,'Appendix 2. Thickness'!$A$3:$B$41,2,FALSE),"") | I46: =IF(H46>0,IF(ISNUMBER(H46),H46,VLOOKUP(F46,'Appendix 2. Thickness'!$A$4:$T$41,(MATCH(H46,'Appendix 2. Thickness'!$C$3:$T$3,0)+2),FALSE)),"") | M46: =IF(B46>0,AK46,"") | N46: =IF(B46>0,(AL46+AM46+AN46),"") | O46: =IF(B46>0,(IF(M46<=N46,"YES","NO")),"") | T46: =($I$13/10)*C46/(2*($I$19*$I$21*$I$22+($I$13/10)*$I$23)) -> #VALUE! | U46: =($I$13/10)*G46/(2*($M$19*$M$21*$M$22+($I$13/10)*$M$23)) -> #VALUE! | V46: =E46*(1-$I$27/100)-$I$28 -> #VALUE! | W46: =I46*(1-$M$27/100)-$M$28 -> #VALUE! | X46: =IF(L46>0,(L46*(1-$I$27/100)-$I$28),0) -> 0 | Y46: =MIN(2.5*(V46-$I$26),2.5*(W46-$M$26)+X46) -> #VALUE! | Z46: =(G46-2*(W46-$M$26))/SIN(J46*PI()/180) -> #VALUE! | AA46: =MIN(MAX(Z46,(W46-$M$26)+(V46-$I$26)+Z46/2),C46) -> #VALUE! | AB46: =MIN(K46,2*AA46) -> #VALUE! | AC46: =MIN(X46,Y46) -> #VALUE! | AD46: =MIN(0.7*I46,6) -> #VALUE! | AE46: =0.5*L46 -> 0 | AF46: =AC46*(AB46-G46/SIN(J46*PI()/180)) -> #VALUE! | AG46: =2*AD46^2 -> #VALUE! | AH46: =IF((X46+AD46*SQRT(2))>Y46,IF(X46<Y46,(AG46-((X46+AD46*SQRT(2))-Y46)^2),0),AG46) -> #VALUE! | AI46: =2*AE46^2 -> 0 | AJ46: =IF((K46/2+AE46*SQRT(2))>AA46,IF(K46/2<AA46,(AI46-((K46/2+AE46*SQRT(2))-AA46)^2),0),AI46) -> #VALUE! | AK46: =T46*Z46*(2-SIN(J46*PI()/180)) -> #VALUE! | AL46: =(2*AA46-Z46)*(V46-T46-$I$26) -> #VALUE! | AM46: =MIN(2*Y46*(W46-U46-$M$26)/SIN(J46*PI()/180),2*Y46*(W46-U46-$M$26)/SIN(J46*PI()/180)*($M$19/$I$19)) -> #VALUE! | AN46: =AF46+AH46+AJ46 -> #VALUE! | AO46: =AK46 -> #VALUE! | AP46: =AL46+AM46+AN46 -> #VALUE!
...

Sheet Appendix 2. Thickness
A1: STANDARD PIPE WALL THICKNESSES AS PER ASME B36.10M AND B36.19M
A3: NPS | B3: OD | C3: Sch5 | D3: Sch5S | E3: Sch10 | F3: Sch10S | G3: Sch20 | H3: Sch30 | I3: STD | J3: Sch40 | K3: Sch40S | L3: Sch60 | M3: XS | N3: Sch80 | O3: Sch80S | P3: Sch100 | Q3: Sch120 | R3: Sch140 | S3: Sch160 | T3: XXS
A4: 0.5 | B4: 21.3 | C4: 1.65 | D4: 1.65 | E4: 2.11 | F4: 2.11 | G4: NA | H4: 2.41 | I4: 2.77 | J4: 2.77 | K4: 2.77 | L4: NA | M4: 3.73 | N4: 3.73 | O4: 3.73 | P4: NA | Q4: NA | R4: NA | S4: 4.78 | T4: 7.47
A5: 0.75 | B5: 26.7 | C5: 1.65 | D5: 1.65 | E5: 2.11 | F5: 2.11 | G5: NA | H5: 2.41 | I5: 2.87 | J5: 2.87 | K5: 2.87 | L5: NA | M5: 3.91 | N5: 3.91 | O5: 3.91 | P5: NA | Q5: NA | R5: NA | S5: 5.56 | T5: 7.82
A6: 1 | B6: 33.4 | C6: 1.65 | D6: 1.65 | E6: 2.77 | F6: 2.77 | G6: NA | H6: 2.9 | I6: 3.38 | J6: 3.38 | K6: 3.38 | L6: NA | M6: 4.55 | N6: 4.55 | O6: 4.55 | P6: NA | Q6: NA | R6: NA | S6: 6.35 | T6: 9.09
A7: 1.5 | B7: 48.3 | C7: 1.65 | D7: 1.65 | E7: 2.77 | F7: 2.77 | G7: NA | H7: 3.18 | I7: 3.68 | J7: 3.68 | K7: 3.68 | L7: NA | M7: 5.08 | N7: 5.08 | O7: 5.08 | P7: NA | Q7: NA | R7: NA | S7: 7.14 | T7: 10.15
A8: 2 | B8: 60.3 | C8: 1.65 | D8: 1.65 | E8: 2.77 | F8: 2.77 | G8: NA | H8: 3.18 | I8: 3.91 | J8: 3.91 | K8: 3.91 | L8: NA | M8: 5.54 | N8: 5.54 | O8: 5.54 | P8: NA | Q8: NA | R8: NA | S8: 8.74 | T8: 11.07
A9: 2.5 | B9: 73 | C9: 2.11 | D9: 2.11 | E9: 3.05 | F9: 3.05 | G9: NA | H9: 4.78 | I9: 5.16 | J9: 5.16 | K9: 5.16 | L9: NA | M9: 7.01 | N9: 7.01 | O9: 7.01 | P9: NA | Q9: NA | R9: NA | S9: 9.53 | T9: 14.02
A10: 3 | B10: 88.9 | C10: 2.11 | D10: 2.11 | E10: 3.05 | F10: 3.05 | G10: NA | H10: 4.78 | I10: 5.49 | J10: 5.49 | K10: 5.49 | L10: NA | M10: 7.62 | N10: 7.62 | O10: 7.62 | P10: NA | Q10: NA | R10: NA | S10: 11.13 | T10: 15.24
A11: 4 | B11: 114.3 | C11: 2.11 | D11: 2.11 | E11: 3.05 | F11: 3.05 | G11: NA | H11: 4.78 | I11: 6.02 | J11: 6.02 | K11: 6.02 | L11: NA | M11: 8.56 | N11: 8.56 | O11: 8.56 | P11: NA | Q11: 11.13 | R11: NA | S11: 13.49 | T11: 17.12
A12: 6 | B12: 168.3 | C12: 2.77 | D12: 2.77 | E12: 3.4 | F12: 3.4 | G12: NA | H12: NA | I12: 7.11 | J12: 7.11 | K12: 7.11 | L12: NA | M12: 10.97 | N12: 10.97 | O12: 10.97 | P12: NA | Q12: 14.27 | R12: NA | S12: 18.26 | T12: 21.95
A13: 8 | B13: 219.1 | C13: 2.77 | D13: 2.77 | E13: 3.76 | F13: 3.76 | G13: 6.35 | H13: 7.04 | I13: 8.18 | J13: 8.18 | K13: 8.18 | L13: 10.31 | M13: 12.7 | N13: 12.7 | O13: 12.7 | P13: 15.09 | Q13: 18.26 | R13: 20.62 | S13: 23.01 | T13: 22.23
A14: 10 | B14: 273 | C14: 3.4 | D14: 3.4 | E14: 4.19 | F14: 4.19 | G14: 6.35 | H14: 7.8 | I14: 9.27 | J14: 9.27 | K14: 9.27 | L14: 12.7 | M14: 12.7 | N14: 15.09 | O14: 12.7 | P14: 18.26 | Q14: 21.44 | R14: 25.4 | S14: 28.58 | T14: 25.4
A15: 12 | B15: 323.8 | C15: 3.96 | D15: 3.96 | E15: 4.57 | F15: 4.57 | G15: 6.35 | H15: 8.38 | I15: 9.53 | J15: 10.31 | K15: 9.53 | L15: 14.27 | M15: 12.7 | N15: 17.48 | O15: 12.7 | P15: 21.44 | Q15: 25.4 | R15: 28.58 | S15: 33.32 | T15: 25.4
A16: 14 | B16: 355.6 | C16: 3.96 | D16: 3.96 | E16: 6.35 | F16: 4.78 | G16: 7.92 | H16: 9.53 | I16: 9.53 | J16: 11.13 | K16: 9.53 | L16: 15.09 | M16: 12.7 | N16: 19.05 | O16: 12.7 | P16: 23.83 | Q16: 27.79 | R16: 31.75 | S16: 35.71 | T16: NA
A17: 16 | B17: 406.4 | C17: 4.19 | D17: 4.19 | E17: 6.35 | F17: 4.78 | G17: 7.92 | H17: 9.53 | I17: 9.53 | J17: 12.7 | K17: 9.53 | L17: 16.66 | M17: 12.7 | N17: 21.44 | O17: 12.7 | P17: 26.19 | Q17: 30.96 | R17: 36.53 | S17: 40.49 | T17: NA
A18: 18 | B18: 457 | C18: 4.19 | D18: 4.19 | E18: 6.35 | F18: 4.78 | G18: 7.92 | H18: 11.13 | I18: 9.53 | J18: 14.27 | K18: 9.53 | L18: 19.05 | M18: 12.7 | N18: 23.83 | O18: 12.7 | P18: 29.36 | Q18: 34.93 | R18: 39.67 | S18: 45.24 | T18: NA
A19: 20 | B19: 508 | C19: 4.78 | D19: 4.78 | E19: 6.35 | F19: 5.54 | G19: 9.53 | H19: 12.7 | I19: 9.53 | J19: 15.09 | K19: 9.53 | L19: 20.62 | M19: 12.7 | N19: 26.19 | O19: 12.7 | P19: 32.54 | Q19: 38.1 | R19: 44.45 | S19: 50.01 | T19: NA
A20: 22 | B20: 559 | C20: 4.78 | D20: 4.78 | E20: 6.35 | F20: 5.54 | G20: 9.53 | H20: 12.7 | I20: 9.53 | J20: NA | K20: NA | L20: 22.23 | M20: 12.7 | N20: 28.58 | O20: NA | P20: 34.93 | Q20: 41.28 | R20: 47.63 | S20: 53.98 | T20: NA
A21: 24 | B21: 610 | C21: 5.54 | D21: 5.54 | E21: 6.35 | F21: 6.35 | G21: 9.53 | H21: 14.27 | I21: 9.53 | J21: 17.48 | K21: 9.53 | L21: 24.61 | M21: 12.7 | N21: 30.96 | O21: 12.7 | P21: 38.89 | Q21: 46.02 | R21: 52.37 | S21: 59.54 | T21: NA
A22: 26 | B22: 660 | C22: NA | D22: NA | E22: 7.92 | F22: NA | G22: 12.7 | H22: NA | I22: 9.53 | J22: NA | K22: NA | L22: NA | M22: 12.7 | N22: NA | O22: NA | P22: NA | Q22: NA | R22: NA | S22: NA | T22: NA
A23: 28 | B23: 711 | C23: NA | D23: NA | E23: 7.92 | F23: NA | G23: 12.7 | H23: 15.88 | I23: 9.53 | J23: NA | K23: NA | L23: NA | M23: 12.7 | N23: NA | O23: NA | P23: NA | Q23: NA | R23: NA | S23: NA | T23: NA
A24: 30 | B24: 762 | C24: 6.35 | D24: 6.35 | E24: 7.92 | F24: 7.92 | G24: 12.7 | H24: 15.88 | I24: 9.53 | J24: NA | K24: NA | L24: NA | M24: 12.7 | N24: NA | O24: NA | P24: NA | Q24: NA | R24: NA | S24: NA | T24: NA
A25: 32 | B25: 813 | C25: NA | D25: NA | E25: 7.92 | F25: NA | G25: 12.7 | H25: 15.88 | I25: 9.53 | J25: 17.48 | K25: NA | L25: NA | M25: 12.7 | N25: NA | O25: NA | P25: NA | Q25: NA | R25: NA | S25: NA | T25: NA
A26: 34 | B26: 864 | C26: NA | D26: NA | E26: 7.92 | F26: NA | G26: 12.7 | H26: 15.88 | I26: 9.53 | J26: 17.48 | K26: NA | L26: NA | M26: 12.7 | N26: NA | O26: NA | P26: NA | Q26: NA | R26: NA | S26: NA | T26: NA
A27: 36 | B27: 914 | C27: NA | D27: NA | E27: 7.92 | F27: NA | G27: 12.7 | H27: 15.88 | I27: 9.53 | J27: 19.05 | K27: NA | L27: NA | M27: 12.7 | N27: NA | O27: NA | P27: NA | Q27: NA | R27: NA | S27: NA | T27: NA
A28: 38 | B28: 965 | C28: NA | D28: NA | E28: NA | F28: NA | G28: NA | H28: NA | I28: 9.53 | J28: NA | K28: NA | L28: NA | M28: 12.7 | N28: NA | O28: NA | P28: NA | Q28: NA | R28: NA | S28: NA | T28: NA
A29: 40 | B29: 1016 | C29: NA | D29: NA | E29: NA | F29: NA | G29: NA | H29: NA | I29: 9.53 | J29: NA | K29: NA | L29: NA | M29: 12.7 | N29: NA | O29: NA | P29: NA | Q29: NA | R29: NA | S29: NA | T29: NA
A30: 42 | B30: 1067 | C30: NA | D30: NA | E30: NA | F30: NA | G30: NA | H30: NA | I30: 9.53 | J30: NA | K30: NA | L30: NA | M30: 12.7 | N30: NA | O30: NA | P30: NA | Q30: NA | R30: NA | S30: NA | T30: NA
A31: 44 | B31: 1118 | C31: NA | D31: NA | E31: NA | F31: NA | G31: NA | H31: NA | I31: 9.53 | J31: NA | K31: NA | L31: NA | M31: 12.7 | N31: NA | O31: NA | P31: NA | Q31: NA | R31: NA | S31: NA | T31: NA
A32: 46 | B32: 1168 | C32: NA | D32: NA | E32: NA | F32: NA | G32: NA | H32: NA | I32: 9.53 | J32: NA | K32: NA | L32: NA | M32: 12.7 | N32: NA | O32: NA | P32: NA | Q32: NA | R32: NA | S32: NA | T32: NA
A33: 48 | B33: 1219 | C33: NA | D33: NA | E33: NA | F33: NA | G33: NA | H33: NA | I33: 9.53 | J33: NA | K33: NA | L33: NA | M33: 12.7 | N33: NA | O33: NA | P33: NA | Q33: NA | R33: NA | S33: NA | T33: NA
A34: 52 | B34: 1321 | C34: NA | D34: NA | E34: NA | F34: NA | G34: NA | H34: NA | I34: NA | J34: NA | K34: NA | L34: NA | M34: NA | N34: NA | O34: NA | P34: NA | Q34: NA | R34: NA | S34: NA | T34: NA
A35: 56 | B35: 1422 | C35: NA | D35: NA | E35: NA | F35: NA | G35: NA | H35: NA | I35: NA | J35: NA | K35: NA | L35: NA | M35: NA | N35: NA | O35: NA | P35: NA | Q35: NA | R35: NA | S35: NA | T35: NA
A36: 60 | B36: 1524 | C36: NA | D36: NA | E36: NA | F36: NA | G36: NA | H36: NA | I36: NA | J36: NA | K36: NA | L36: NA | M36: NA | N36: NA | O36: NA | P36: NA | Q36: NA | R36: NA | S36: NA | T36: NA
A37: 64 | B37: 1626 | C37: NA | D37: NA | E37: NA | F37: NA | G37: NA | H37: NA | I37: NA | J37: NA | K37: NA | L37: NA | M37: NA | N37: NA | O37: NA | P37: NA | Q37: NA | R37: NA | S37: NA | T37: NA
A38: 68 | B38: 1727 | C38: NA | D38: NA | E38: NA | F38: NA | G38: NA | H38: NA | I38: NA | J38: NA | K38: NA | L38: NA | M38: NA | N38: NA | O38: NA | P38: NA | Q38: NA | R38: NA | S38: NA | T38: NA
A39: 72 | B39: 1829 | C39: NA | D39: NA | E39: NA | F39: NA | G39: NA | H39: NA | I39: NA | J39: NA | K39: NA | L39: NA | M39: NA | N39: NA | O39: NA | P39: NA | Q39: NA | R39: NA | S39: NA | T39: NA
A40: 76 | B40: 1930 | C40: NA | D40: NA | E40: NA | F40: NA | G40: NA | H40: NA | I40: NA | J40: NA | K40: NA | L40: NA | M40: NA | N40: NA | O40: NA | P40: NA | Q40: NA | R40: NA | S40: NA | T40: NA
A41: 80 | B41: 2032 | C41: NA | D41: NA | E41: NA | F41: NA | G41: NA | H41: NA | I41: NA | J41: NA | K41: NA | L41: NA | M41: NA | N41: NA | O41: NA | P41: NA | Q41: NA | R41: NA | S41: NA | T41: NA
...
